Workbook

Sheet MLB Lines
A1: FECHA | B1: TEAM A | C1: wRCa | D1: SP | E1: FIPa | F1: BP xFIPa | G1: xFIPtot | H1: TEAM B | I1: wRCb | J1: SP2 | K1: FIPb | L1: BP xFIPb | M1: xFIPtot2 | O1: tA | P1: tB | Q1: TOTAL | S1: hTeam | T1: PF | U1: W | V1: MPH | W1: T | Y1: GAME | Z1: TEAM 1 | AA1: TEAM 2 | AB1: mTotals | AC1: preTotals | AD1: spread # | AE1: team | AF1: mSpread | AG1: ML %
A2: 46106 | B2: YANKEES | C2: =VLOOKUP(B2, 'MLB Data'!$B$5:$D$34, 3, FALSE) | D2: FRIED | E2: 3.37 | F2: =VLOOKUP(B2, 'MLB Data'!$F$2:$H$34, 3, FALSE) | G2: =IF((E2*0.6+F2*0.4)<2.5, 2.8, IF((E2*0.6+F2*0.4)>5.5, 5.2, (E2*0.6+F2*0.4))) | H2: GIANTS | I2: =VLOOKUP(H2, 'MLB Data'!$B$5:$D$34, 3, FALSE) | J2: WEBB | K2: 3.03 | L2: =VLOOKUP(H2, 'MLB Data'!$F$2:$H$34, 3, FALSE) | M2: =IF((K2*0.6+L2*0.4)<2.5, 2.8, IF((K2*0.6+L2*0.4)>5.5, 5.2, (K2*0.6+L2*0.4))) | O2: =(C2/100) * 4.45 * (M2 / 4.2) * T2 | P2: =(I2/100) * 4.45 * (G2 / 4.2) * T2 | Q2: =(O2+P2) | S2: =H2 | T2: =IF(S2="ROCKIES",1.13,IF(S2="ATHLETICS",1.03,IF(S2="ROYALS",1.03,IF(S2="TWINS",1,IF(S2="TIGERS",1,IF(S2="MARLINS",1.01,IF(S2="REDS",1.05,IF(S2="RED SOX",1.04,IF(S2="YANKEES",1.02,IF(S2="DODGERS",0.99,IF(S2="PADRES",0.96,IF(S2="CUBS",0.98,IF(S2="GIANTS",0.97,IF(S2="MARINERS",0.94,IF(S2="RANGERS",1,IF(S2="ASTROS",0.99,IF(S2="BRAVES",1,IF(S2="METS",0.96,IF(S2="PHILLIES",1.02,IF(S2="BLUE JAYS",1.01,IF(S2="ORIOLES",0.99,IF(S2="RAYS",1.01,IF(S2="GUARDIANS",0.99,IF(S2="WHITE SOX",0.98,IF(S2="ANGELS",1.01,IF(S2="D-BACKS",1.01,IF(S2="BREWERS",0.99,IF(S2="CARDINALS",0.96,IF(S2="PIRATES",1.02,IF(S2="NATIONALS",1,1))))))))))))))))))))))))))))))*IF(W2="",1,(1+((W2-70)/10*0.035)))*IF(U2="DOME",1,IF(U2="IN",1-(V2*0.01),IF(U2="OUT",1+(V2*0.01),IF(OR(U2="L-R",U2="R-L"),1+(V2*0.005),1)))) | U2: OUT | W2: 75 | Y2: =B2 & " vs. " & H2 | Z2: =TRIM(LEFT(Y2, FIND("vs.", Y2)-1)) | AA2: =TRIM(MID(Y2, FIND(" vs. ", Y2)+4, 100)) | AB2: =IF(Q2 > VALUE(AC2), "O " & AC2, IF(Q2 < VALUE(AC2), "U " & AC2, AC2)) | AC2: =IF(OR(O2="-", P2="-"), "-", MROUND(O2 + P2, 0.5)) | AD2: =VALUE(TRIM(RIGHT(AF2, LEN(AF2) - FIND(" ", AF2)))) | AE2: =LEFT(AF2,FIND(" ",AF2)-1) | AF2: =IF(OR(O2="-", P2="-"), "-", IF(MROUND(ABS(O2-P2),0.5)<=0.5, IF(O2>P2, B2 & " ML", H2 & " ML"), IF(MROUND(ABS(O2-P2),0.5)=1, IF(O2>P2, H2 & " +1.5", B2 & " +1.5"), IF(O2>P2, B2 & " -1.5", H2 & " -1.5") ) ) ) | AG2: =_xlfn.LET( _xlpm.winA, O2^1.83 / (O2^1.83 + P2^1.83), _xlpm.winB, 1 - _xlpm.winA, _xlpm.oddsA, IF(_xlpm.winA >= 0.5, "-" & ROUND(_xlpm.winA / (1 - _xlpm.winA) * 100, 0), "+" & ROUND((1 - _xlpm.winA) / _xlpm.winA * 100, 0)), _xlpm.oddsB, IF(_xlpm.winB >= 0.5, "-" & ROUND(_xlpm.winB / (1 - _xlpm.winB) * 100, 0), "+" & ROUND((1 - _xlpm.winB) / _xlpm.winB * 100, 0)), _xlpm.oddsA & " / " & _xlpm.oddsB )
A3: 46107 | B3: PIRATES | C3: =VLOOKUP(B3, 'MLB Data'!$B$5:$D$34, 3, FALSE) | D3: SKENES | E3: 3.03 | F3: =VLOOKUP(B3, 'MLB Data'!$F$2:$H$34, 3, FALSE) | G3: =IF((E3*0.6+F3*0.4)<2.5, 2.8, IF((E3*0.6+F3*0.4)>5.5, 5.2, (E3*0.6+F3*0.4))) | H3: METS | I3: =VLOOKUP(H3, 'MLB Data'!$B$5:$D$34, 3, FALSE) | J3: PERALTA | K3: 3.85 | L3: =VLOOKUP(H3, 'MLB Data'!$F$2:$H$34, 3, FALSE) | M3: =IF((K3*0.6+L3*0.4)<2.5, 2.8, IF((K3*0.6+L3*0.4)>5.5, 5.2, (K3*0.6+L3*0.4))) | O3: =(C3/100) * 4.45 * (M3 / 4.2) * T3 | P3: =(I3/100) * 4.45 * (G3 / 4.2) * T3 | Q3: =(O3+P3) | S3: =H3 | T3: =IF(S3="ROCKIES",1.13,IF(S3="ATHLETICS",1.03,IF(S3="ROYALS",1.03,IF(S3="TWINS",1,IF(S3="TIGERS",1,IF(S3="MARLINS",1.01,IF(S3="REDS",1.05,IF(S3="RED SOX",1.04,IF(S3="YANKEES",1.02,IF(S3="DODGERS",0.99,IF(S3="PADRES",0.96,IF(S3="CUBS",0.98,IF(S3="GIANTS",0.97,IF(S3="MARINERS",0.94,IF(S3="RANGERS",1,IF(S3="ASTROS",0.99,IF(S3="BRAVES",1,IF(S3="METS",0.96,IF(S3="PHILLIES",1.02,IF(S3="BLUE JAYS",1.01,IF(S3="ORIOLES",0.99,IF(S3="RAYS",1.01,IF(S3="GUARDIANS",0.99,IF(S3="WHITE SOX",0.98,IF(S3="ANGELS",1.01,IF(S3="D-BACKS",1.01,IF(S3="BREWERS",0.99,IF(S3="CARDINALS",0.96,IF(S3="PIRATES",1.02,IF(S3="NATIONALS",1,1))))))))))))))))))))))))))))))*IF(W3="",1,(1+((W3-70)/10*0.035)))*IF(U3="DOME",1,IF(U3="IN",1-(V3*0.01),IF(U3="OUT",1+(V3*0.01),IF(OR(U3="L-R",U3="R-L"),1+(V3*0.005),1)))) | U3: OUT | W3: 66 | Y3: =B3 & " vs. " & H3 | Z3: =TRIM(LEFT(Y3, FIND("vs.", Y3)-1)) | AA3: =TRIM(MID(Y3, FIND(" vs. ", Y3)+4, 100)) | AB3: =IF(Q3 > VALUE(AC3), "O " & AC3, IF(Q3 < VALUE(AC3), "U " & AC3, AC3)) | AC3: =IF(OR(O3="-", P3="-"), "-", MROUND(O3 + P3, 0.5)) | AD3: =VALUE(TRIM(RIGHT(AF3, LEN(AF3) - FIND(" ", AF3)))) | AE3: =LEFT(AF3,FIND(" ",AF3)-1) | AF3: =IF(OR(O3="-", P3="-"), "-", IF(MROUND(ABS(O3-P3),0.5)<=0.5, IF(O3>P3, B3 & " ML", H3 & " ML"), IF(MROUND(ABS(O3-P3),0.5)=1, IF(O3>P3, H3 & " +1.5", B3 & " +1.5"), IF(O3>P3, B3 & " -1.5", H3 & " -1.5") ) ) ) | AG3: =_xlfn.LET( _xlpm.winA, O3^1.83 / (O3^1.83 + P3^1.83), _xlpm.winB, 1 - _xlpm.winA, _xlpm.oddsA, IF(_xlpm.winA >= 0.5, "-" & ROUND(_xlpm.winA / (1 - _xlpm.winA) * 100, 0), "+" & ROUND((1 - _xlpm.winA) / _xlpm.winA * 100, 0)), _xlpm.oddsB, IF(_xlpm.winB >= 0.5, "-" & ROUND(_xlpm.winB / (1 - _xlpm.winB) * 100, 0), "+" & ROUND((1 - _xlpm.winB) / _xlpm.winB * 100, 0)), _xlpm.oddsA & " / " & _xlpm.oddsB)
A4: 46107 | B4: WHITE SOX | C4: =VLOOKUP(B4, 'MLB Data'!$B$5:$D$34, 3, FALSE) | D4: SMITH | E4: 4.23 | F4: =VLOOKUP(B4, 'MLB Data'!$F$2:$H$34, 3, FALSE) | G4: =IF((E4*0.6+F4*0.4)<2.5, 2.8, IF((E4*0.6+F4*0.4)>5.5, 5.2, (E4*0.6+F4*0.4))) | H4: BREWERS | I4: =VLOOKUP(H4, 'MLB Data'!$B$5:$D$34, 3, FALSE) | J4: MISIOROWSKI | K4: 3.56 | L4: =VLOOKUP(H4, 'MLB Data'!$F$2:$H$34, 3, FALSE) | M4: =IF((K4*0.6+L4*0.4)<2.5, 2.8, IF((K4*0.6+L4*0.4)>5.5, 5.2, (K4*0.6+L4*0.4))) | O4: =(C4/100) * 4.45 * (M4 / 4.2) * T4 | P4: =(I4/100) * 4.45 * (G4 / 4.2) * T4 | Q4: =(O4+P4) | S4: =H4 | T4: =IF(S4="ROCKIES",1.13,IF(S4="ATHLETICS",1.03,IF(S4="ROYALS",1.03,IF(S4="TWINS",1,IF(S4="TIGERS",1,IF(S4="MARLINS",1.01,IF(S4="REDS",1.05,IF(S4="RED SOX",1.04,IF(S4="YANKEES",1.02,IF(S4="DODGERS",0.99,IF(S4="PADRES",0.96,IF(S4="CUBS",0.98,IF(S4="GIANTS",0.97,IF(S4="MARINERS",0.94,IF(S4="RANGERS",1,IF(S4="ASTROS",0.99,IF(S4="BRAVES",1,IF(S4="METS",0.96,IF(S4="PHILLIES",1.02,IF(S4="BLUE JAYS",1.01,IF(S4="ORIOLES",0.99,IF(S4="RAYS",1.01,IF(S4="GUARDIANS",0.99,IF(S4="WHITE SOX",0.98,IF(S4="ANGELS",1.01,IF(S4="D-BACKS",1.01,IF(S4="BREWERS",0.99,IF(S4="CARDINALS",0.96,IF(S4="PIRATES",1.02,IF(S4="NATIONALS",1,1))))))))))))))))))))))))))))))*IF(W4="",1,(1+((W4-70)/10*0.035)))*IF(U4="DOME",1,IF(U4="IN",1-(V4*0.01),IF(U4="OUT",1+(V4*0.01),IF(OR(U4="L-R",U4="R-L"),1+(V4*0.005),1)))) | U4: OUT | W4: 56 | Y4: =B4 & " vs. " & H4 | Z4: =TRIM(LEFT(Y4, FIND("vs.", Y4)-1)) | AA4: =TRIM(MID(Y4, FIND(" vs. ", Y4)+4, 100)) | AB4: =IF(Q4 > VALUE(AC4), "O " & AC4, IF(Q4 < VALUE(AC4), "U " & AC4, AC4)) | AC4: =IF(OR(O4="-", P4="-"), "-", MROUND(O4 + P4, 0.5)) | AD4: =VALUE(TRIM(RIGHT(AF4, LEN(AF4) - FIND(" ", AF4)))) | AE4: =LEFT(AF4,FIND(" ",AF4)-1) | AF4: =IF(OR(O4="-", P4="-"), "-", IF(MROUND(ABS(O4-P4),0.5)<=0.5, IF(O4>P4, B4 & " ML", H4 & " ML"), IF(MROUND(ABS(O4-P4),0.5)=1, IF(O4>P4, H4 & " +1.5", B4 & " +1.5"), IF(O4>P4, B4 & " -1.5", H4 & " -1.5") ) ) ) | AG4: =_xlfn.LET( _xlpm.winA, O4^1.83 / (O4^1.83 + P4^1.83), _xlpm.winB, 1 - _xlpm.winA, _xlpm.oddsA, IF(_xlpm.winA >= 0.5, "-" & ROUND(_xlpm.winA / (1 - _xlpm.winA) * 100, 0), "+" & ROUND((1 - _xlpm.winA) / _xlpm.winA * 100, 0)), _xlpm.oddsB, IF(_xlpm.winB >= 0.5, "-" & ROUND(_xlpm.winB / (1 - _xlpm.winB) * 100, 0), "+" & ROUND((1 - _xlpm.winB) / _xlpm.winB * 100, 0)), _xlpm.oddsA & " / " & _xlpm.oddsB)
A5: 46107 | B5: NATIONALS | C5: =VLOOKUP(B5, 'MLB Data'!$B$5:$D$34, 3, FALSE) | D5: CAVALLI | E5: 3.93 | F5: =VLOOKUP(B5, 'MLB Data'!$F$2:$H$34, 3, FALSE) | G5: =IF((E5*0.6+F5*0.4)<2.5, 2.8, IF((E5*0.6+F5*0.4)>5.5, 5.2, (E5*0.6+F5*0.4))) | H5: CUBS | I5: =VLOOKUP(H5, 'MLB Data'!$B$5:$D$34, 3, FALSE) | J5: BOYD | K5: 4.22 | L5: =VLOOKUP(H5, 'MLB Data'!$F$2:$H$34, 3, FALSE) | M5: =IF((K5*0.6+L5*0.4)<2.5, 2.8, IF((K5*0.6+L5*0.4)>5.5, 5.2, (K5*0.6+L5*0.4))) | O5: =(C5/100) * 4.45 * (M5 / 4.2) * T5 | P5: =(I5/100) * 4.45 * (G5 / 4.2) * T5 | Q5: =(O5+P5) | S5: =H5 | T5: =IF(S5="ROCKIES",1.13,IF(S5="ATHLETICS",1.03,IF(S5="ROYALS",1.03,IF(S5="TWINS",1,IF(S5="TIGERS",1,IF(S5="MARLINS",1.01,IF(S5="REDS",1.05,IF(S5="RED SOX",1.04,IF(S5="YANKEES",1.02,IF(S5="DODGERS",0.99,IF(S5="PADRES",0.96,IF(S5="CUBS",0.98,IF(S5="GIANTS",0.97,IF(S5="MARINERS",0.94,IF(S5="RANGERS",1,IF(S5="ASTROS",0.99,IF(S5="BRAVES",1,IF(S5="METS",0.96,IF(S5="PHILLIES",1.02,IF(S5="BLUE JAYS",1.01,IF(S5="ORIOLES",0.99,IF(S5="RAYS",1.01,IF(S5="GUARDIANS",0.99,IF(S5="WHITE SOX",0.98,IF(S5="ANGELS",1.01,IF(S5="D-BACKS",1.01,IF(S5="BREWERS",0.99,IF(S5="CARDINALS",0.96,IF(S5="PIRATES",1.02,IF(S5="NATIONALS",1,1))))))))))))))))))))))))))))))*IF(W5="",1,(1+((W5-70)/10*0.035)))*IF(U5="DOME",1,IF(U5="IN",1-(V5*0.01),IF(U5="OUT",1+(V5*0.01),IF(OR(U5="L-R",U5="R-L"),1+(V5*0.005),1)))) | U5: IN | W5: 57 | Y5: =B5 & " vs. " & H5 | Z5: =TRIM(LEFT(Y5, FIND("vs.", Y5)-1)) | AA5: =TRIM(MID(Y5, FIND(" vs. ", Y5)+4, 100)) | AB5: =IF(Q5 > VALUE(AC5), "O " & AC5, IF(Q5 < VALUE(AC5), "U " & AC5, AC5)) | AC5: =IF(OR(O5="-", P5="-"), "-", MROUND(O5 + P5, 0.5)) | AD5: =VALUE(TRIM(RIGHT(AF5, LEN(AF5) - FIND(" ", AF5)))) | AE5: =LEFT(AF5,FIND(" ",AF5)-1) | AF5: =IF(OR(O5="-", P5="-"), "-", IF(MROUND(ABS(O5-P5),0.5)<=0.5, IF(O5>P5, B5 & " ML", H5 & " ML"), IF(MROUND(ABS(O5-P5),0.5)=1, IF(O5>P5, H5 & " +1.5", B5 & " +1.5"), IF(O5>P5, B5 & " -1.5", H5 & " -1.5") ) ) ) | AG5: =_xlfn.LET( _xlpm.winA, O5^1.83 / (O5^1.83 + P5^1.83), _xlpm.winB, 1 - _xlpm.winA, _xlpm.oddsA, IF(_xlpm.winA >= 0.5, "-" & ROUND(_xlpm.winA / (1 - _xlpm.winA) * 100, 0), "+" & ROUND((1 - _xlpm.winA) / _xlpm.winA * 100, 0)), _xlpm.oddsB, IF(_xlpm.winB >= 0.5, "-" & ROUND(_xlpm.winB / (1 - _xlpm.winB) * 100, 0), "+" & ROUND((1 - _xlpm.winB) / _xlpm.winB * 100, 0)), _xlpm.oddsA & " / " & _xlpm.oddsB)
A6: 46107 | B6: TWINS | C6: =VLOOKUP(B6, 'MLB Data'!$B$5:$D$34, 3, FALSE) | D6: RYAN | E6: 3.66 | F6: =VLOOKUP(B6, 'MLB Data'!$F$2:$H$34, 3, FALSE) | G6: =IF((E6*0.6+F6*0.4)<2.5, 2.8, IF((E6*0.6+F6*0.4)>5.5, 5.2, (E6*0.6+F6*0.4))) | H6: ORIOLES | I6: =VLOOKUP(H6, 'MLB Data'!$B$5:$D$34, 3, FALSE) | J6: ROGERS | K6: 3.64 | L6: =VLOOKUP(H6, 'MLB Data'!$F$2:$H$34, 3, FALSE) | M6: =IF((K6*0.6+L6*0.4)<2.5, 2.8, IF((K6*0.6+L6*0.4)>5.5, 5.2, (K6*0.6+L6*0.4))) | O6: =(C6/100) * 4.45 * (M6 / 4.2) * T6 | P6: =(I6/100) * 4.45 * (G6 / 4.2) * T6 | Q6: =(O6+P6) | S6: =H6 | T6: =IF(S6="ROCKIES",1.13,IF(S6="ATHLETICS",1.03,IF(S6="ROYALS",1.03,IF(S6="TWINS",1,IF(S6="TIGERS",1,IF(S6="MARLINS",1.01,IF(S6="REDS",1.05,IF(S6="RED SOX",1.04,IF(S6="YANKEES",1.02,IF(S6="DODGERS",0.99,IF(S6="PADRES",0.96,IF(S6="CUBS",0.98,IF(S6="GIANTS",0.97,IF(S6="MARINERS",0.94,IF(S6="RANGERS",1,IF(S6="ASTROS",0.99,IF(S6="BRAVES",1,IF(S6="METS",0.96,IF(S6="PHILLIES",1.02,IF(S6="BLUE JAYS",1.01,IF(S6="ORIOLES",0.99,IF(S6="RAYS",1.01,IF(S6="GUARDIANS",0.99,IF(S6="WHITE SOX",0.98,IF(S6="ANGELS",1.01,IF(S6="D-BACKS",1.01,IF(S6="BREWERS",0.99,IF(S6="CARDINALS",0.96,IF(S6="PIRATES",1.02,IF(S6="NATIONALS",1,1))))))))))))))))))))))))))))))*IF(W6="",1,(1+((W6-70)/10*0.035)))*IF(U6="DOME",1,IF(U6="IN",1-(V6*0.01),IF(U6="OUT",1+(V6*0.01),IF(OR(U6="L-R",U6="R-L"),1+(V6*0.005),1)))) | U6: OUT | W6: 78 | Y6: =B6 & " vs. " & H6 | Z6: =TRIM(LEFT(Y6, FIND("vs.", Y6)-1)) | AA6: =TRIM(MID(Y6, FIND(" vs. ", Y6)+4, 100)) | AB6: =IF(Q6 > VALUE(AC6), "O " & AC6, IF(Q6 < VALUE(AC6), "U " & AC6, AC6)) | AC6: =IF(OR(O6="-", P6="-"), "-", MROUND(O6 + P6, 0.5)) | AD6: =VALUE(TRIM(RIGHT(AF6, LEN(AF6) - FIND(" ", AF6)))) | AE6: =LEFT(AF6,FIND(" ",AF6)-1) | AF6: =IF(OR(O6="-", P6="-"), "-", IF(MROUND(ABS(O6-P6),0.5)<=0.5, IF(O6>P6, B6 & " ML", H6 & " ML"), IF(MROUND(ABS(O6-P6),0.5)=1, IF(O6>P6, H6 & " +1.5", B6 & " +1.5"), IF(O6>P6, B6 & " -1.5", H6 & " -1.5") ) ) ) | AG6: =_xlfn.LET( _xlpm.winA, O6^1.83 / (O6^1.83 + P6^1.83), _xlpm.winB, 1 - _xlpm.winA, _xlpm.oddsA, IF(_xlpm.winA >= 0.5, "-" & ROUND(_xlpm.winA / (1 - _xlpm.winA) * 100, 0), "+" & ROUND((1 - _xlpm.winA) / _xlpm.winA * 100, 0)), _xlpm.oddsB, IF(_xlpm.winB >= 0.5, "-" & ROUND(_xlpm.winB / (1 - _xlpm.winB) * 100, 0), "+" & ROUND((1 - _xlpm.winB) / _xlpm.winB * 100, 0)), _xlpm.oddsA & " / " & _xlpm.oddsB)
A7: 46107 | B7: RED SOX | C7: =VLOOKUP(B7, 'MLB Data'!$B$5:$D$34, 3, FALSE) | D7: CROCHET | E7: 2.64 | F7: =VLOOKUP(B7, 'MLB Data'!$F$2:$H$34, 3, FALSE) | G7: =IF((E7*0.6+F7*0.4)<2.5, 2.8, IF((E7*0.6+F7*0.4)>5.5, 5.2, (E7*0.6+F7*0.4))) | H7: REDS | I7: =VLOOKUP(H7, 'MLB Data'!$B$5:$D$34, 3, FALSE) | J7: ABBOTT | K7: 4.31 | L7: =VLOOKUP(H7, 'MLB Data'!$F$2:$H$34, 3, FALSE) | M7: =IF((K7*0.6+L7*0.4)<2.5, 2.8, IF((K7*0.6+L7*0.4)>5.5, 5.2, (K7*0.6+L7*0.4))) | O7: =(C7/100) * 4.45 * (M7 / 4.2) * T7 | P7: =(I7/100) * 4.45 * (G7 / 4.2) * T7 | Q7: =(O7+P7) | S7: =H7 | T7: =IF(S7="ROCKIES",1.13,IF(S7="ATHLETICS",1.03,IF(S7="ROYALS",1.03,IF(S7="TWINS",1,IF(S7="TIGERS",1,IF(S7="MARLINS",1.01,IF(S7="REDS",1.05,IF(S7="RED SOX",1.04,IF(S7="YANKEES",1.02,IF(S7="DODGERS",0.99,IF(S7="PADRES",0.96,IF(S7="CUBS",0.98,IF(S7="GIANTS",0.97,IF(S7="MARINERS",0.94,IF(S7="RANGERS",1,IF(S7="ASTROS",0.99,IF(S7="BRAVES",1,IF(S7="METS",0.96,IF(S7="PHILLIES",1.02,IF(S7="BLUE JAYS",1.01,IF(S7="ORIOLES",0.99,IF(S7="RAYS",1.01,IF(S7="GUARDIANS",0.99,IF(S7="WHITE SOX",0.98,IF(S7="ANGELS",1.01,IF(S7="D-BACKS",1.01,IF(S7="BREWERS",0.99,IF(S7="CARDINALS",0.96,IF(S7="PIRATES",1.02,IF(S7="NATIONALS",1,1))))))))))))))))))))))))))))))*IF(W7="",1,(1+((W7-70)/10*0.035)))*IF(U7="DOME",1,IF(U7="IN",1-(V7*0.01),IF(U7="OUT",1+(V7*0.01),IF(OR(U7="L-R",U7="R-L"),1+(V7*0.005),1)))) | U7: OUT | W7: 80 | Y7: =B7 & " vs. " & H7 | Z7: =TRIM(LEFT(Y7, FIND("vs.", Y7)-1)) | AA7: =TRIM(MID(Y7, FIND(" vs. ", Y7)+4, 100)) | AB7: =IF(Q7 > VALUE(AC7), "O " & AC7, IF(Q7 < VALUE(AC7), "U " & AC7, AC7)) | AC7: =IF(OR(O7="-", P7="-"), "-", MROUND(O7 + P7, 0.5)) | AD7: =VALUE(TRIM(RIGHT(AF7, LEN(AF7) - FIND(" ", AF7)))) | AE7: =LEFT(AF7,FIND(" ",AF7)-1) | AF7: =IF(OR(O7="-", P7="-"), "-", IF(MROUND(ABS(O7-P7),0.5)<=0.5, IF(O7>P7, B7 & " ML", H7 & " ML"), IF(MROUND(ABS(O7-P7),0.5)=1, IF(O7>P7, H7 & " +1.5", B7 & " +1.5"), IF(O7>P7, B7 & " -1.5", H7 & " -1.5") ) ) ) | AG7: =_xlfn.LET( _xlpm.winA, O7^1.83 / (O7^1.83 + P7^1.83), _xlpm.winB, 1 - _xlpm.winA, _xlpm.oddsA, IF(_xlpm.winA >= 0.5, "-" & ROUND(_xlpm.winA / (1 - _xlpm.winA) * 100, 0), "+" & ROUND((1 - _xlpm.winA) / _xlpm.winA * 100, 0)), _xlpm.oddsB, IF(_xlpm.winB >= 0.5, "-" & ROUND(_xlpm.winB / (1 - _xlpm.winB) * 100, 0), "+" & ROUND((1 - _xlpm.winB) / _xlpm.winB * 100, 0)), _xlpm.oddsA & " / " & _xlpm.oddsB)
A8: 46107 | B8: ANGELS | C8: =VLOOKUP(B8, 'MLB Data'!$B$5:$D$34, 3, FALSE) | D8: SORIANO | E8: 3.54 | F8: =VLOOKUP(B8, 'MLB Data'!$F$2:$H$34, 3, FALSE) | G8: =IF((E8*0.6+F8*0.4)<2.5, 2.8, IF((E8*0.6+F8*0.4)>5.5, 5.2, (E8*0.6+F8*0.4))) | H8: ASTROS | I8: =VLOOKUP(H8, 'MLB Data'!$B$5:$D$34, 3, FALSE) | J8: BROWN | K8: 3.19 | L8: =VLOOKUP(H8, 'MLB Data'!$F$2:$H$34, 3, FALSE) | M8: =IF((K8*0.6+L8*0.4)<2.5, 2.8, IF((K8*0.6+L8*0.4)>5.5, 5.2, (K8*0.6+L8*0.4))) | O8: =(C8/100) * 4.45 * (M8 / 4.2) * T8 | P8: =(I8/100) * 4.45 * (G8 / 4.2) * T8 | Q8: =(O8+P8) | S8: =H8 | T8: =IF(S8="ROCKIES",1.13,IF(S8="ATHLETICS",1.03,IF(S8="ROYALS",1.03,IF(S8="TWINS",1,IF(S8="TIGERS",1,IF(S8="MARLINS",1.01,IF(S8="REDS",1.05,IF(S8="RED SOX",1.04,IF(S8="YANKEES",1.02,IF(S8="DODGERS",0.99,IF(S8="PADRES",0.96,IF(S8="CUBS",0.98,IF(S8="GIANTS",0.97,IF(S8="MARINERS",0.94,IF(S8="RANGERS",1,IF(S8="ASTROS",0.99,IF(S8="BRAVES",1,IF(S8="METS",0.96,IF(S8="PHILLIES",1.02,IF(S8="BLUE JAYS",1.01,IF(S8="ORIOLES",0.99,IF(S8="RAYS",1.01,IF(S8="GUARDIANS",0.99,IF(S8="WHITE SOX",0.98,IF(S8="ANGELS",1.01,IF(S8="D-BACKS",1.01,IF(S8="BREWERS",0.99,IF(S8="CARDINALS",0.96,IF(S8="PIRATES",1.02,IF(S8="NATIONALS",1,1))))))))))))))))))))))))))))))*IF(W8="",1,(1+((W8-70)/10*0.035)))*IF(U8="DOME",1,IF(U8="IN",1-(V8*0.01),IF(U8="OUT",1+(V8*0.01),IF(OR(U8="L-R",U8="R-L"),1+(V8*0.005),1)))) | U8: OUT | W8: 85 | Y8: =B8 & " vs. " & H8 | Z8: =TRIM(LEFT(Y8, FIND("vs.", Y8)-1)) | AA8: =TRIM(MID(Y8, FIND(" vs. ", Y8)+4, 100)) | AB8: =IF(Q8 > VALUE(AC8), "O " & AC8, IF(Q8 < VALUE(AC8), "U " & AC8, AC8)) | AC8: =IF(OR(O8="-", P8="-"), "-", MROUND(O8 + P8, 0.5)) | AD8: =VALUE(TRIM(RIGHT(AF8, LEN(AF8) - FIND(" ", AF8)))) | AE8: =LEFT(AF8,FIND(" ",AF8)-1) | AF8: =IF(OR(O8="-", P8="-"), "-", IF(MROUND(ABS(O8-P8),0.5)<=0.5, IF(O8>P8, B8 & " ML", H8 & " ML"), IF(MROUND(ABS(O8-P8),0.5)=1, IF(O8>P8, H8 & " +1.5", B8 & " +1.5"), IF(O8>P8, B8 & " -1.5", H8 & " -1.5") ) ) ) | AG8: =_xlfn.LET( _xlpm.winA, O8^1.83 / (O8^1.83 + P8^1.83), _xlpm.winB, 1 - _xlpm.winA, _xlpm.oddsA, IF(_xlpm.winA >= 0.5, "-" & ROUND(_xlpm.winA / (1 - _xlpm.winA) * 100, 0), "+" & ROUND((1 - _xlpm.winA) / _xlpm.winA * 100, 0)), _xlpm.oddsB, IF(_xlpm.winB >= 0.5, "-" & ROUND(_xlpm.winB / (1 - _xlpm.winB) * 100, 0), "+" & ROUND((1 - _xlpm.winB) / _xlpm.winB * 100, 0)), _xlpm.oddsA & " / " & _xlpm.oddsB)
A9: 46107 | B9: TIGERS | C9: =VLOOKUP(B9, 'MLB Data'!$B$5:$D$34, 3, FALSE) | D9: SKUBAL | E9: 2.66 | F9: =VLOOKUP(B9, 'MLB Data'!$F$2:$H$34, 3, FALSE) | G9: =IF((E9*0.6+F9*0.4)<2.5, 2.8, IF((E9*0.6+F9*0.4)>5.5, 5.2, (E9*0.6+F9*0.4))) | H9: PADRES | I9: =VLOOKUP(H9, 'MLB Data'!$B$5:$D$34, 3, FALSE) | J9: PIVETTA | K9: 3.85 | L9: =VLOOKUP(H9, 'MLB Data'!$F$2:$H$34, 3, FALSE) | M9: =IF((K9*0.6+L9*0.4)<2.5, 2.8, IF((K9*0.6+L9*0.4)>5.5, 5.2, (K9*0.6+L9*0.4))) | O9: =(C9/100) * 4.45 * (M9 / 4.2) * T9 | P9: =(I9/100) * 4.45 * (G9 / 4.2) * T9 | Q9: =(O9+P9) | S9: =H9 | T9: =IF(S9="ROCKIES",1.13,IF(S9="ATHLETICS",1.03,IF(S9="ROYALS",1.03,IF(S9="TWINS",1,IF(S9="TIGERS",1,IF(S9="MARLINS",1.01,IF(S9="REDS",1.05,IF(S9="RED SOX",1.04,IF(S9="YANKEES",1.02,IF(S9="DODGERS",0.99,IF(S9="PADRES",0.96,IF(S9="CUBS",0.98,IF(S9="GIANTS",0.97,IF(S9="MARINERS",0.94,IF(S9="RANGERS",1,IF(S9="ASTROS",0.99,IF(S9="BRAVES",1,IF(S9="METS",0.96,IF(S9="PHILLIES",1.02,IF(S9="BLUE JAYS",1.01,IF(S9="ORIOLES",0.99,IF(S9="RAYS",1.01,IF(S9="GUARDIANS",0.99,IF(S9="WHITE SOX",0.98,IF(S9="ANGELS",1.01,IF(S9="D-BACKS",1.01,IF(S9="BREWERS",0.99,IF(S9="CARDINALS",0.96,IF(S9="PIRATES",1.02,IF(S9="NATIONALS",1,1))))))))))))))))))))))))))))))*IF(W9="",1,(1+((W9-70)/10*0.035)))*IF(U9="DOME",1,IF(U9="IN",1-(V9*0.01),IF(U9="OUT",1+(V9*0.01),IF(OR(U9="L-R",U9="R-L"),1+(V9*0.005),1)))) | U9: OUT | W9: 78 | Y9: =B9 & " vs. " & H9 | Z9: =TRIM(LEFT(Y9, FIND("vs.", Y9)-1)) | AA9: =TRIM(MID(Y9, FIND(" vs. ", Y9)+4, 100)) | AB9: =IF(Q9 > VALUE(AC9), "O " & AC9, IF(Q9 < VALUE(AC9), "U " & AC9, AC9)) | AC9: =IF(OR(O9="-", P9="-"), "-", MROUND(O9 + P9, 0.5)) | AD9: =VALUE(TRIM(RIGHT(AF9, LEN(AF9) - FIND(" ", AF9)))) | AE9: =LEFT(AF9,FIND(" ",AF9)-1) | AF9: =IF(OR(O9="-", P9="-"), "-", IF(MROUND(ABS(O9-P9),0.5)<=0.5, IF(O9>P9, B9 & " ML", H9 & " ML"), IF(MROUND(ABS(O9-P9),0.5)=1, IF(O9>P9, H9 & " +1.5", B9 & " +1.5"), IF(O9>P9, B9 & " -1.5", H9 & " -1.5") ) ) ) | AG9: =_xlfn.LET( _xlpm.winA, O9^1.83 / (O9^1.83 + P9^1.83), _xlpm.winB, 1 - _xlpm.winA, _xlpm.oddsA, IF(_xlpm.winA >= 0.5, "-" & ROUND(_xlpm.winA / (1 - _xlpm.winA) * 100, 0), "+" & ROUND((1 - _xlpm.winA) / _xlpm.winA * 100, 0)), _xlpm.oddsB, IF(_xlpm.winB >= 0.5, "-" & ROUND(_xlpm.winB / (1 - _xlpm.winB) * 100, 0), "+" & ROUND((1 - _xlpm.winB) / _xlpm.winB * 100, 0)), _xlpm.oddsA & " / " & _xlpm.oddsB)
A10: 46107 | B10: RAYS | C10: =VLOOKUP(B10, 'MLB Data'!$B$5:$D$34, 3, FALSE) | D10: RASMUSSEN | E10: 3.72 | F10: =VLOOKUP(B10, 'MLB Data'!$F$2:$H$34, 3, FALSE) | G10: =IF((E10*0.6+F10*0.4)<2.5, 2.8, IF((E10*0.6+F10*0.4)>5.5, 5.2, (E10*0.6+F10*0.4))) | H10: CARDINALS | I10: =VLOOKUP(H10, 'MLB Data'!$B$5:$D$34, 3, FALSE) | J10: LIBERATORE | K10: 4.31 | L10: =VLOOKUP(H10, 'MLB Data'!$F$2:$H$34, 3, FALSE) | M10: =IF((K10*0.6+L10*0.4)<2.5, 2.8, IF((K10*0.6+L10*0.4)>5.5, 5.2, (K10*0.6+L10*0.4))) | O10: =(C10/100) * 4.45 * (M10 / 4.2) * T10 | P10: =(I10/100) * 4.45 * (G10 / 4.2) * T10 | Q10: =(O10+P10) | S10: =H10 | T10: =IF(S10="ROCKIES",1.13,IF(S10="ATHLETICS",1.03,IF(S10="ROYALS",1.03,IF(S10="TWINS",1,IF(S10="TIGERS",1,IF(S10="MARLINS",1.01,IF(S10="REDS",1.05,IF(S10="RED SOX",1.04,IF(S10="YANKEES",1.02,IF(S10="DODGERS",0.99,IF(S10="PADRES",0.96,IF(S10="CUBS",0.98,IF(S10="GIANTS",0.97,IF(S10="MARINERS",0.94,IF(S10="RANGERS",1,IF(S10="ASTROS",0.99,IF(S10="BRAVES",1,IF(S10="METS",0.96,IF(S10="PHILLIES",1.02,IF(S10="BLUE JAYS",1.01,IF(S10="ORIOLES",0.99,IF(S10="RAYS",1.01,IF(S10="GUARDIANS",0.99,IF(S10="WHITE SOX",0.98,IF(S10="ANGELS",1.01,IF(S10="D-BACKS",1.01,IF(S10="BREWERS",0.99,IF(S10="CARDINALS",0.96,IF(S10="PIRATES",1.02,IF(S10="NATIONALS",1,1))))))))))))))))))))))))))))))*IF(W10="",1,(1+((W10-70)/10*0.035)))*IF(U10="DOME",1,IF(U10="IN",1-(V10*0.01),IF(U10="OUT",1+(V10*0.01),IF(OR(U10="L-R",U10="R-L"),1+(V10*0.005),1)))) | U10: OUT | W10: 90 | Y10: =B10 & " vs. " & H10 | Z10: =TRIM(LEFT(Y10, FIND("vs.", Y10)-1)) | AA10: =TRIM(MID(Y10, FIND(" vs. ", Y10)+4, 100)) | AB10: =IF(Q10 > VALUE(AC10), "O " & AC10, IF(Q10 < VALUE(AC10), "U " & AC10, AC10)) | AC10: =IF(OR(O10="-", P10="-"), "-", MROUND(O10 + P10, 0.5)) | AD10: =VALUE(TRIM(RIGHT(AF10, LEN(AF10) - FIND(" ", AF10)))) | AE10: =LEFT(AF10,FIND(" ",AF10)-1) | AF10: =IF(OR(O10="-", P10="-"), "-", IF(MROUND(ABS(O10-P10),0.5)<=0.5, IF(O10>P10, B10 & " ML", H10 & " ML"), IF(MROUND(ABS(O10-P10),0.5)=1, IF(O10>P10, H10 & " +1.5", B10 & " +1.5"), IF(O10>P10, B10 & " -1.5", H10 & " -1.5") ) ) ) | AG10: =_xlfn.LET( _xlpm.winA, O10^1.83 / (O10^1.83 + P10^1.83), _xlpm.winB, 1 - _xlpm.winA, _xlpm.oddsA, IF(_xlpm.winA >= 0.5, "-" & ROUND(_xlpm.winA / (1 - _xlpm.winA) * 100, 0), "+" & ROUND((1 - _xlpm.winA) / _xlpm.winA * 100, 0)), _xlpm.oddsB, IF(_xlpm.winB >= 0.5, "-" & ROUND(_xlpm.winB / (1 - _xlpm.winB) * 100, 0), "+" & ROUND((1 - _xlpm.winB) / _xlpm.winB * 100, 0)), _xlpm.oddsA & " / " & _xlpm.oddsB)
A11: 46107 | B11: RANGERS | C11: =VLOOKUP(B11, 'MLB Data'!$B$5:$D$34, 3, FALSE) | D11: EOVALDI | E11: 3.03 | F11: =VLOOKUP(B11, 'MLB Data'!$F$2:$H$34, 3, FALSE) | G11: =IF((E11*0.6+F11*0.4)<2.5, 2.8, IF((E11*0.6+F11*0.4)>5.5, 5.2, (E11*0.6+F11*0.4))) | H11: PHILLIES | I11: =VLOOKUP(H11, 'MLB Data'!$B$5:$D$34, 3, FALSE) | J11: SANCHEZ | K11: 2.77 | L11: =VLOOKUP(H11, 'MLB Data'!$F$2:$H$34, 3, FALSE) | M11: =IF((K11*0.6+L11*0.4)<2.5, 2.8, IF((K11*0.6+L11*0.4)>5.5, 5.2, (K11*0.6+L11*0.4))) | O11: =(C11/100) * 4.45 * (M11 / 4.2) * T11 | P11: =(I11/100) * 4.45 * (G11 / 4.2) * T11 | Q11: =(O11+P11) | S11: =H11 | T11: =IF(S11="ROCKIES",1.13,IF(S11="ATHLETICS",1.03,IF(S11="ROYALS",1.03,IF(S11="TWINS",1,IF(S11="TIGERS",1,IF(S11="MARLINS",1.01,IF(S11="REDS",1.05,IF(S11="RED SOX",1.04,IF(S11="YANKEES",1.02,IF(S11="DODGERS",0.99,IF(S11="PADRES",0.96,IF(S11="CUBS",0.98,IF(S11="GIANTS",0.97,IF(S11="MARINERS",0.94,IF(S11="RANGERS",1,IF(S11="ASTROS",0.99,IF(S11="BRAVES",1,IF(S11="METS",0.96,IF(S11="PHILLIES",1.02,IF(S11="BLUE JAYS",1.01,IF(S11="ORIOLES",0.99,IF(S11="RAYS",1.01,IF(S11="GUARDIANS",0.99,IF(S11="WHITE SOX",0.98,IF(S11="ANGELS",1.01,IF(S11="D-BACKS",1.01,IF(S11="BREWERS",0.99,IF(S11="CARDINALS",0.96,IF(S11="PIRATES",1.02,IF(S11="NATIONALS",1,1))))))))))))))))))))))))))))))*IF(W11="",1,(1+((W11-70)/10*0.035)))*IF(U11="DOME",1,IF(U11="IN",1-(V11*0.01),IF(U11="OUT",1+(V11*0.01),IF(OR(U11="L-R",U11="R-L"),1+(V11*0.005),1)))) | U11: OUT | W11: 76 | Y11: =B11 & " vs. " & H11 | Z11: =TRIM(LEFT(Y11, FIND("vs.", Y11)-1)) | AA11: =TRIM(MID(Y11, FIND(" vs. ", Y11)+4, 100)) | AB11: =IF(Q11 > VALUE(AC11), "O " & AC11, IF(Q11 < VALUE(AC11), "U " & AC11, AC11)) | AC11: =IF(OR(O11="-", P11="-"), "-", MROUND(O11 + P11, 0.5)) | AD11: =VALUE(TRIM(RIGHT(AF11, LEN(AF11) - FIND(" ", AF11)))) | AE11: =LEFT(AF11,FIND(" ",AF11)-1) | AF11: =IF(OR(O11="-", P11="-"), "-", IF(MROUND(ABS(O11-P11),0.5)<=0.5, IF(O11>P11, B11 & " ML", H11 & " ML"), IF(MROUND(ABS(O11-P11),0.5)=1, IF(O11>P11, H11 & " +1.5", B11 & " +1.5"), IF(O11>P11, B11 & " -1.5", H11 & " -1.5") ) ) ) | AG11: =_xlfn.LET( _xlpm.winA, O11^1.83 / (O11^1.83 + P11^1.83), _xlpm.winB, 1 - _xlpm.winA, _xlpm.oddsA, IF(_xlpm.winA >= 0.5, "-" & ROUND(_xlpm.winA / (1 - _xlpm.winA) * 100, 0), "+" & ROUND((1 - _xlpm.winA) / _xlpm.winA * 100, 0)), _xlpm.oddsB, IF(_xlpm.winB >= 0.5, "-" & ROUND(_xlpm.winB / (1 - _xlpm.winB) * 100, 0), "+" & ROUND((1 - _xlpm.winB) / _xlpm.winB * 100, 0)), _xlpm.oddsA & " / " & _xlpm.oddsB)
A12: 46107 | B12: D-BACKS | C12: =VLOOKUP(B12, 'MLB Data'!$B$5:$D$34, 3, FALSE) | D12: GALLEN | E12: 4.12 | F12: =VLOOKUP(B12, 'MLB Data'!$F$2:$H$34, 3, FALSE) | G12: =IF((E12*0.6+F12*0.4)<2.5, 2.8, IF((E12*0.6+F12*0.4)>5.5, 5.2, (E12*0.6+F12*0.4))) | H12: DODGERS | I12: =VLOOKUP(H12, 'MLB Data'!$B$5:$D$34, 3, FALSE) | J12: YAMAMOTO | K12: 3.05 | L12: =VLOOKUP(H12, 'MLB Data'!$F$2:$H$34, 3, FALSE) | M12: =IF((K12*0.6+L12*0.4)<2.5, 2.8, IF((K12*0.6+L12*0.4)>5.5, 5.2, (K12*0.6+L12*0.4))) | O12: =(C12/100) * 4.45 * (M12 / 4.2) * T12 | P12: =(I12/100) * 4.45 * (G12 / 4.2) * T12 | Q12: =(O12+P12) | S12: =H12 | T12: =IF(S12="ROCKIES",1.13,IF(S12="ATHLETICS",1.03,IF(S12="ROYALS",1.03,IF(S12="TWINS",1,IF(S12="TIGERS",1,IF(S12="MARLINS",1.01,IF(S12="REDS",1.05,IF(S12="RED SOX",1.04,IF(S12="YANKEES",1.02,IF(S12="DODGERS",0.99,IF(S12="PADRES",0.96,IF(S12="CUBS",0.98,IF(S12="GIANTS",0.97,IF(S12="MARINERS",0.94,IF(S12="RANGERS",1,IF(S12="ASTROS",0.99,IF(S12="BRAVES",1,IF(S12="METS",0.96,IF(S12="PHILLIES",1.02,IF(S12="BLUE JAYS",1.01,IF(S12="ORIOLES",0.99,IF(S12="RAYS",1.01,IF(S12="GUARDIANS",0.99,IF(S12="WHITE SOX",0.98,IF(S12="ANGELS",1.01,IF(S12="D-BACKS",1.01,IF(S12="BREWERS",0.99,IF(S12="CARDINALS",0.96,IF(S12="PIRATES",1.02,IF(S12="NATIONALS",1,1))))))))))))))))))))))))))))))*IF(W12="",1,(1+((W12-70)/10*0.035)))*IF(U12="DOME",1,IF(U12="IN",1-(V12*0.01),IF(U12="OUT",1+(V12*0.01),IF(OR(U12="L-R",U12="R-L"),1+(V12*0.005),1)))) | U12: OUT | W12: 78 | Y12: =B12 & " vs. " & H12 | Z12: =TRIM(LEFT(Y12, FIND("vs.", Y12)-1)) | AA12: =TRIM(MID(Y12, FIND(" vs. ", Y12)+4, 100)) | AB12: =IF(Q12 > VALUE(AC12), "O " & AC12, IF(Q12 < VALUE(AC12), "U " & AC12, AC12)) | AC12: =IF(OR(O12="-", P12="-"), "-", MROUND(O12 + P12, 0.5)) | AD12: =VALUE(TRIM(RIGHT(AF12, LEN(AF12) - FIND(" ", AF12)))) | AE12: =LEFT(AF12,FIND(" ",AF12)-1) | AF12: =IF(OR(O12="-", P12="-"), "-", IF(MROUND(ABS(O12-P12),0.5)<=0.5, IF(O12>P12, B12 & " ML", H12 & " ML"), IF(MROUND(ABS(O12-P12),0.5)=1, IF(O12>P12, H12 & " +1.5", B12 & " +1.5"), IF(O12>P12, B12 & " -1.5", H12 & " -1.5") ) ) ) | AG12: =_xlfn.LET( _xlpm.winA, O12^1.83 / (O12^1.83 + P12^1.83), _xlpm.winB, 1 - _xlpm.winA, _xlpm.oddsA, IF(_xlpm.winA >= 0.5, "-" & ROUND(_xlpm.winA / (1 - _xlpm.winA) * 100, 0), "+" & ROUND((1 - _xlpm.winA) / _xlpm.winA * 100, 0)), _xlpm.oddsB, IF(_xlpm.winB >= 0.5, "-" & ROUND(_xlpm.winB / (1 - _xlpm.winB) * 100, 0), "+" & ROUND((1 - _xlpm.winB) / _xlpm.winB * 100, 0)), _xlpm.oddsA & " / " & _xlpm.oddsB)
A13: 46107 | B13: GUARDIANS | C13: =VLOOKUP(B13, 'MLB Data'!$B$5:$D$34, 3, FALSE) | D13: BIBEE | E13: 4.17 | F13: =VLOOKUP(B13, 'MLB Data'!$F$2:$H$34, 3, FALSE) | G13: =IF((E13*0.6+F13*0.4)<2.5, 2.8, IF((E13*0.6+F13*0.4)>5.5, 5.2, (E13*0.6+F13*0.4))) | H13: MARINERS | I13: =VLOOKUP(H13, 'MLB Data'!$B$5:$D$34, 3, FALSE) | J13: GILBERT | K13: 2.95 | L13: =VLOOKUP(H13, 'MLB Data'!$F$2:$H$34, 3, FALSE) | M13: =IF((K13*0.6+L13*0.4)<2.5, 2.8, IF((K13*0.6+L13*0.4)>5.5, 5.2, (K13*0.6+L13*0.4))) | O13: =(C13/100) * 4.45 * (M13 / 4.2) * T13 | P13: =(I13/100) * 4.45 * (G13 / 4.2) * T13 | Q13: =(O13+P13) | S13: =H13 | T13: =IF(S13="ROCKIES",1.13,IF(S13="ATHLETICS",1.03,IF(S13="ROYALS",1.03,IF(S13="TWINS",1,IF(S13="TIGERS",1,IF(S13="MARLINS",1.01,IF(S13="REDS",1.05,IF(S13="RED SOX",1.04,IF(S13="YANKEES",1.02,IF(S13="DODGERS",0.99,IF(S13="PADRES",0.96,IF(S13="CUBS",0.98,IF(S13="GIANTS",0.97,IF(S13="MARINERS",0.94,IF(S13="RANGERS",1,IF(S13="ASTROS",0.99,IF(S13="BRAVES",1,IF(S13="METS",0.96,IF(S13="PHILLIES",1.02,IF(S13="BLUE JAYS",1.01,IF(S13="ORIOLES",0.99,IF(S13="RAYS",1.01,IF(S13="GUARDIANS",0.99,IF(S13="WHITE SOX",0.98,IF(S13="ANGELS",1.01,IF(S13="D-BACKS",1.01,IF(S13="BREWERS",0.99,IF(S13="CARDINALS",0.96,IF(S13="PIRATES",1.02,IF(S13="NATIONALS",1,1))))))))))))))))))))))))))))))*IF(W13="",1,(1+((W13-70)/10*0.035)))*IF(U13="DOME",1,IF(U13="IN",1-(V13*0.01),IF(U13="OUT",1+(V13*0.01),IF(OR(U13="L-R",U13="R-L"),1+(V13*0.005),1)))) | U13: OUT | W13: 50 | Y13: =B13 & " vs. " & H13 | Z13: =TRIM(LEFT(Y13, FIND("vs.", Y13)-1)) | AA13: =TRIM(MID(Y13, FIND(" vs. ", Y13)+4, 100)) | AB13: =IF(Q13 > VALUE(AC13), "O " & AC13, IF(Q13 < VALUE(AC13), "U " & AC13, AC13)) | AC13: =IF(OR(O13="-", P13="-"), "-", MROUND(O13 + P13, 0.5)) | AD13: =VALUE(TRIM(RIGHT(AF13, LEN(AF13) - FIND(" ", AF13)))) | AE13: =LEFT(AF13,FIND(" ",AF13)-1) | AF13: =IF(OR(O13="-", P13="-"), "-", IF(MROUND(ABS(O13-P13),0.5)<=0.5, IF(O13>P13, B13 & " ML", H13 & " ML"), IF(MROUND(ABS(O13-P13),0.5)=1, IF(O13>P13, H13 & " +1.5", B13 & " +1.5"), IF(O13>P13, B13 & " -1.5", H13 & " -1.5") ) ) ) | AG13: =_xlfn.LET( _xlpm.winA, O13^1.83 / (O13^1.83 + P13^1.83), _xlpm.winB, 1 - _xlpm.winA, _xlpm.oddsA, IF(_xlpm.winA >= 0.5, "-" & ROUND(_xlpm.winA / (1 - _xlpm.winA) * 100, 0), "+" & ROUND((1 - _xlpm.winA) / _xlpm.winA * 100, 0)), _xlpm.oddsB, IF(_xlpm.winB >= 0.5, "-" & ROUND(_xlpm.winB / (1 - _xlpm.winB) * 100, 0), "+" & ROUND((1 - _xlpm.winB) / _xlpm.winB * 100, 0)), _xlpm.oddsA & " / " & _xlpm.oddsB)
A14: 46108 | B14: YANKEES | C14: =VLOOKUP(B14, 'MLB Data'!$B$5:$D$34, 3, FALSE) | D14: SCHLITTLER | E14: 3.77 | F14: =VLOOKUP(B14, 'MLB Data'!$F$2:$H$34, 3, FALSE) | G14: =IF((E14*0.6+F14*0.4)<2.5, 2.8, IF((E14*0.6+F14*0.4)>5.5, 5.2, (E14*0.6+F14*0.4))) | H14: GIANTS | I14: =VLOOKUP(H14, 'MLB Data'!$B$5:$D$34, 3, FALSE) | J14: RAY | K14: 4.29 | L14: =VLOOKUP(H14, 'MLB Data'!$F$2:$H$34, 3, FALSE) | M14: =IF((K14*0.6+L14*0.4)<2.5, 2.8, IF((K14*0.6+L14*0.4)>5.5, 5.2, (K14*0.6+L14*0.4))) | O14: =(C14/100) * 4.45 * (M14 / 4.2) * T14 | P14: =(I14/100) * 4.45 * (G14 / 4.2) * T14 | Q14: =(O14+P14) | S14: =H14 | T14: =IF(S14="ROCKIES",1.13,IF(S14="ATHLETICS",1.03,IF(S14="ROYALS",1.03,IF(S14="TWINS",1,IF(S14="TIGERS",1,IF(S14="MARLINS",1.01,IF(S14="REDS",1.05,IF(S14="RED SOX",1.04,IF(S14="YANKEES",1.02,IF(S14="DODGERS",0.99,IF(S14="PADRES",0.96,IF(S14="CUBS",0.98,IF(S14="GIANTS",0.97,IF(S14="MARINERS",0.94,IF(S14="RANGERS",1,IF(S14="ASTROS",0.99,IF(S14="BRAVES",1,IF(S14="METS",0.96,IF(S14="PHILLIES",1.02,IF(S14="BLUE JAYS",1.01,IF(S14="ORIOLES",0.99,IF(S14="RAYS",1.01,IF(S14="GUARDIANS",0.99,IF(S14="WHITE SOX",0.98,IF(S14="ANGELS",1.01,IF(S14="D-BACKS",1.01,IF(S14="BREWERS",0.99,IF(S14="CARDINALS",0.96,IF(S14="PIRATES",1.02,IF(S14="NATIONALS",1,1))))))))))))))))))))))))))))))*IF(W14="",1,(1+((W14-70)/10*0.035)))*IF(U14="DOME",1,IF(U14="IN",1-(V14*0.01),IF(U14="OUT",1+(V14*0.01),IF(OR(U14="L-R",U14="R-L"),1+(V14*0.005),1)))) | W14: 74 | Y14: =B14 & " vs. " & H14 | Z14: =TRIM(LEFT(Y14, FIND("vs.", Y14)-1)) | AA14: =TRIM(MID(Y14, FIND(" vs. ", Y14)+4, 100)) | AB14: =IF(Q14 > VALUE(AC14), "O " & AC14, IF(Q14 < VALUE(AC14), "U " & AC14, AC14)) | AC14: =IF(OR(O14="-", P14="-"), "-", MROUND(O14 + P14, 0.5)) | AD14: =VALUE(TRIM(RIGHT(AF14, LEN(AF14) - FIND(" ", AF14)))) | AE14: =LEFT(AF14,FIND(" ",AF14)-1) | AF14: =IF(OR(O14="-", P14="-"), "-", IF(MROUND(ABS(O14-P14),0.5)<=0.5, IF(O14>P14, B14 & " ML", H14 & " ML"), IF(MROUND(ABS(O14-P14),0.5)=1, IF(O14>P14, H14 & " +1.5", B14 & " +1.5"), IF(O14>P14, B14 & " -1.5", H14 & " -1.5") ) ) ) | AG14: =_xlfn.LET( _xlpm.winA, O14^1.83 / (O14^1.83 + P14^1.83), _xlpm.winB, 1 - _xlpm.winA, _xlpm.oddsA, IF(_xlpm.winA >= 0.5, "-" & ROUND(_xlpm.winA / (1 - _xlpm.winA) * 100, 0), "+" & ROUND((1 - _xlpm.winA) / _xlpm.winA * 100, 0)), _xlpm.oddsB, IF(_xlpm.winB >= 0.5, "-" & ROUND(_xlpm.winB / (1 - _xlpm.winB) * 100, 0), "+" & ROUND((1 - _xlpm.winB) / _xlpm.winB * 100, 0)), _xlpm.oddsA & " / " & _xlpm.oddsB)
A15: 46108 | B15: ATHLETICS | C15: =VLOOKUP(B15, 'MLB Data'!$B$5:$D$34, 3, FALSE) | D15: SEVERINO | E15: 4.63 | F15: =VLOOKUP(B15, 'MLB Data'!$F$2:$H$34, 3, FALSE) | G15: =IF((E15*0.6+F15*0.4)<2.5, 2.8, IF((E15*0.6+F15*0.4)>5.5, 5.2, (E15*0.6+F15*0.4))) | H15: BLUE JAYS | I15: =VLOOKUP(H15, 'MLB Data'!$B$5:$D$34, 3, FALSE) | J15: GAUSMAN | K15: 3.77 | L15: =VLOOKUP(H15, 'MLB Data'!$F$2:$H$34, 3, FALSE) | M15: =IF((K15*0.6+L15*0.4)<2.5, 2.8, IF((K15*0.6+L15*0.4)>5.5, 5.2, (K15*0.6+L15*0.4))) | O15: =(C15/100) * 4.45 * (M15 / 4.2) * T15 | P15: =(I15/100) * 4.45 * (G15 / 4.2) * T15 | Q15: =(O15+P15) | S15: =H15 | T15: =IF(S15="ROCKIES",1.13,IF(S15="ATHLETICS",1.03,IF(S15="ROYALS",1.03,IF(S15="TWINS",1,IF(S15="TIGERS",1,IF(S15="MARLINS",1.01,IF(S15="REDS",1.05,IF(S15="RED SOX",1.04,IF(S15="YANKEES",1.02,IF(S15="DODGERS",0.99,IF(S15="PADRES",0.96,IF(S15="CUBS",0.98,IF(S15="GIANTS",0.97,IF(S15="MARINERS",0.94,IF(S15="RANGERS",1,IF(S15="ASTROS",0.99,IF(S15="BRAVES",1,IF(S15="METS",0.96,IF(S15="PHILLIES",1.02,IF(S15="BLUE JAYS",1.01,IF(S15="ORIOLES",0.99,IF(S15="RAYS",1.01,IF(S15="GUARDIANS",0.99,IF(S15="WHITE SOX",0.98,IF(S15="ANGELS",1.01,IF(S15="D-BACKS",1.01,IF(S15="BREWERS",0.99,IF(S15="CARDINALS",0.96,IF(S15="PIRATES",1.02,IF(S15="NATIONALS",1,1))))))))))))))))))))))))))))))*IF(W15="",1,(1+((W15-70)/10*0.035)))*IF(U15="DOME",1,IF(U15="IN",1-(V15*0.01),IF(U15="OUT",1+(V15*0.01),IF(OR(U15="L-R",U15="R-L"),1+(V15*0.005),1)))) | U15: DOME | W15: 29 | Y15: =B15 & " vs. " & H15 | Z15: =TRIM(LEFT(Y15, FIND("vs.", Y15)-1)) | AA15: =TRIM(MID(Y15, FIND(" vs. ", Y15)+4, 100)) | AB15: =IF(Q15 > VALUE(AC15), "O " & AC15, IF(Q15 < VALUE(AC15), "U " & AC15, AC15)) | AC15: =IF(OR(O15="-", P15="-"), "-", MROUND(O15 + P15, 0.5)) | AD15: =VALUE(TRIM(RIGHT(AF15, LEN(AF15) - FIND(" ", AF15)))) | AE15: =LEFT(AF15,FIND(" ",AF15)-1) | AF15: =IF(OR(O15="-", P15="-"), "-", IF(MROUND(ABS(O15-P15),0.5)<=0.5, IF(O15>P15, B15 & " ML", H15 & " ML"), IF(MROUND(ABS(O15-P15),0.5)=1, IF(O15>P15, H15 & " +1.5", B15 & " +1.5"), IF(O15>P15, B15 & " -1.5", H15 & " -1.5") ) ) ) | AG15: =_xlfn.LET( _xlpm.winA, O15^1.83 / (O15^1.83 + P15^1.83), _xlpm.winB, 1 - _xlpm.winA, _xlpm.oddsA, IF(_xlpm.winA >= 0.5, "-" & ROUND(_xlpm.winA / (1 - _xlpm.winA) * 100, 0), "+" & ROUND((1 - _xlpm.winA) / _xlpm.winA * 100, 0)), _xlpm.oddsB, IF(_xlpm.winB >= 0.5, "-" & ROUND(_xlpm.winB / (1 - _xlpm.winB) * 100, 0), "+" & ROUND((1 - _xlpm.winB) / _xlpm.winB * 100, 0)), _xlpm.oddsA & " / " & _xlpm.oddsB)
A16: 46108 | B16: ROCKIES | C16: =VLOOKUP(B16, 'MLB Data'!$B$5:$D$34, 3, FALSE) | D16: FREELAND | E16: 4.29 | F16: =VLOOKUP(B16, 'MLB Data'!$F$2:$H$34, 3, FALSE) | G16: =IF((E16*0.6+F16*0.4)<2.5, 2.8, IF((E16*0.6+F16*0.4)>5.5, 5.2, (E16*0.6+F16*0.4))) | H16: MARLINS | I16: =VLOOKUP(H16, 'MLB Data'!$B$5:$D$34, 3, FALSE) | J16: ALCANTARA | K16: 4.19 | L16: =VLOOKUP(H16, 'MLB Data'!$F$2:$H$34, 3, FALSE) | M16: =IF((K16*0.6+L16*0.4)<2.5, 2.8, IF((K16*0.6+L16*0.4)>5.5, 5.2, (K16*0.6+L16*0.4))) | O16: =(C16/100) * 4.45 * (M16 / 4.2) * T16 | P16: =(I16/100) * 4.45 * (G16 / 4.2) * T16 | Q16: =(O16+P16) | S16: =H16 | T16: =IF(S16="ROCKIES",1.13,IF(S16="ATHLETICS",1.03,IF(S16="ROYALS",1.03,IF(S16="TWINS",1,IF(S16="TIGERS",1,IF(S16="MARLINS",1.01,IF(S16="REDS",1.05,IF(S16="RED SOX",1.04,IF(S16="YANKEES",1.02,IF(S16="DODGERS",0.99,IF(S16="PADRES",0.96,IF(S16="CUBS",0.98,IF(S16="GIANTS",0.97,IF(S16="MARINERS",0.94,IF(S16="RANGERS",1,IF(S16="ASTROS",0.99,IF(S16="BRAVES",1,IF(S16="METS",0.96,IF(S16="PHILLIES",1.02,IF(S16="BLUE JAYS",1.01,IF(S16="ORIOLES",0.99,IF(S16="RAYS",1.01,IF(S16="GUARDIANS",0.99,IF(S16="WHITE SOX",0.98,IF(S16="ANGELS",1.01,IF(S16="D-BACKS",1.01,IF(S16="BREWERS",0.99,IF(S16="CARDINALS",0.96,IF(S16="PIRATES",1.02,IF(S16="NATIONALS",1,1))))))))))))))))))))))))))))))*IF(W16="",1,(1+((W16-70)/10*0.035)))*IF(U16="DOME",1,IF(U16="IN",1-(V16*0.01),IF(U16="OUT",1+(V16*0.01),IF(OR(U16="L-R",U16="R-L"),1+(V16*0.005),1)))) | U16: DOME | W16: 78 | Y16: =B16 & " vs. " & H16 | Z16: =TRIM(LEFT(Y16, FIND("vs.", Y16)-1)) | AA16: =TRIM(MID(Y16, FIND(" vs. ", Y16)+4, 100)) | AB16: =IF(Q16 > VALUE(AC16), "O " & AC16, IF(Q16 < VALUE(AC16), "U " & AC16, AC16)) | AC16: =IF(OR(O16="-", P16="-"), "-", MROUND(O16 + P16, 0.5)) | AD16: =VALUE(TRIM(RIGHT(AF16, LEN(AF16) - FIND(" ", AF16)))) | AE16: =LEFT(AF16,FIND(" ",AF16)-1) | AF16: =IF(OR(O16="-", P16="-"), "-", IF(MROUND(ABS(O16-P16),0.5)<=0.5, IF(O16>P16, B16 & " ML", H16 & " ML"), IF(MROUND(ABS(O16-P16),0.5)=1, IF(O16>P16, H16 & " +1.5", B16 & " +1.5"), IF(O16>P16, B16 & " -1.5", H16 & " -1.5") ) ) ) | AG16: =_xlfn.LET( _xlpm.winA, O16^1.83 / (O16^1.83 + P16^1.83), _xlpm.winB, 1 - _xlpm.winA, _xlpm.oddsA, IF(_xlpm.winA >= 0.5, "-" & ROUND(_xlpm.winA / (1 - _xlpm.winA) * 100, 0), "+" & ROUND((1 - _xlpm.winA) / _xlpm.winA * 100, 0)), _xlpm.oddsB, IF(_xlpm.winB >= 0.5, "-" & ROUND(_xlpm.winB / (1 - _xlpm.winB) * 100, 0), "+" & ROUND((1 - _xlpm.winB) / _xlpm.winB * 100, 0)), _xlpm.oddsA & " / " & _xlpm.oddsB)
A17: 46108 | B17: ROYALS | C17: =VLOOKUP(B17, 'MLB Data'!$B$5:$D$34, 3, FALSE) | D17: RAGANS | E17: 2.45 | F17: =VLOOKUP(B17, 'MLB Data'!$F$2:$H$34, 3, FALSE) | G17: =IF((E17*0.6+F17*0.4)<2.5, 2.8, IF((E17*0.6+F17*0.4)>5.5, 5.2, (E17*0.6+F17*0.4))) | H17: BRAVES | I17: =VLOOKUP(H17, 'MLB Data'!$B$5:$D$34, 3, FALSE) | J17: SALE | K17: 2.98 | L17: =VLOOKUP(H17, 'MLB Data'!$F$2:$H$34, 3, FALSE) | M17: =IF((K17*0.6+L17*0.4)<2.5, 2.8, IF((K17*0.6+L17*0.4)>5.5, 5.2, (K17*0.6+L17*0.4))) | O17: =(C17/100) * 4.45 * (M17 / 4.2) * T17 | P17: =(I17/100) * 4.45 * (G17 / 4.2) * T17 | Q17: =(O17+P17) | S17: =H17 | T17: =IF(S17="ROCKIES",1.13,IF(S17="ATHLETICS",1.03,IF(S17="ROYALS",1.03,IF(S17="TWINS",1,IF(S17="TIGERS",1,IF(S17="MARLINS",1.01,IF(S17="REDS",1.05,IF(S17="RED SOX",1.04,IF(S17="YANKEES",1.02,IF(S17="DODGERS",0.99,IF(S17="PADRES",0.96,IF(S17="CUBS",0.98,IF(S17="GIANTS",0.97,IF(S17="MARINERS",0.94,IF(S17="RANGERS",1,IF(S17="ASTROS",0.99,IF(S17="BRAVES",1,IF(S17="METS",0.96,IF(S17="PHILLIES",1.02,IF(S17="BLUE JAYS",1.01,IF(S17="ORIOLES",0.99,IF(S17="RAYS",1.01,IF(S17="GUARDIANS",0.99,IF(S17="WHITE SOX",0.98,IF(S17="ANGELS",1.01,IF(S17="D-BACKS",1.01,IF(S17="BREWERS",0.99,IF(S17="CARDINALS",0.96,IF(S17="PIRATES",1.02,IF(S17="NATIONALS",1,1))))))))))))))))))))))))))))))*IF(W17="",1,(1+((W17-70)/10*0.035)))*IF(U17="DOME",1,IF(U17="IN",1-(V17*0.01),IF(U17="OUT",1+(V17*0.01),IF(OR(U17="L-R",U17="R-L"),1+(V17*0.005),1)))) | U17: OUT | W17: 78 | Y17: =B17 & " vs. " & H17 | Z17: =TRIM(LEFT(Y17, FIND("vs.", Y17)-1)) | AA17: =TRIM(MID(Y17, FIND(" vs. ", Y17)+4, 100)) | AB17: =IF(Q17 > VALUE(AC17), "O " & AC17, IF(Q17 < VALUE(AC17), "U " & AC17, AC17)) | AC17: =IF(OR(O17="-", P17="-"), "-", MROUND(O17 + P17, 0.5)) | AD17: =VALUE(TRIM(RIGHT(AF17, LEN(AF17) - FIND(" ", AF17)))) | AE17: =LEFT(AF17,FIND(" ",AF17)-1) | AF17: =IF(OR(O17="-", P17="-"), "-", IF(MROUND(ABS(O17-P17),0.5)<=0.5, IF(O17>P17, B17 & " ML", H17 & " ML"), IF(MROUND(ABS(O17-P17),0.5)=1, IF(O17>P17, H17 & " +1.5", B17 & " +1.5"), IF(O17>P17, B17 & " -1.5", H17 & " -1.5") ) ) ) | AG17: =_xlfn.LET( _xlpm.winA, O17^1.83 / (O17^1.83 + P17^1.83), _xlpm.winB, 1 - _xlpm.winA, _xlpm.oddsA, IF(_xlpm.winA >= 0.5, "-" & ROUND(_xlpm.winA / (1 - _xlpm.winA) * 100, 0), "+" & ROUND((1 - _xlpm.winA) / _xlpm.winA * 100, 0)), _xlpm.oddsB, IF(_xlpm.winB >= 0.5, "-" & ROUND(_xlpm.winB / (1 - _xlpm.winB) * 100, 0), "+" & ROUND((1 - _xlpm.winB) / _xlpm.winB * 100, 0)), _xlpm.oddsA & " / " & _xlpm.oddsB)
A18: 46108 | B18: ANGELS | C18: =VLOOKUP(B18, 'MLB Data'!$B$5:$D$34, 3, FALSE) | D18: KIKUCHI | E18: 4.28 | F18: =VLOOKUP(B18, 'MLB Data'!$F$2:$H$34, 3, FALSE) | G18: =IF((E18*0.6+F18*0.4)<2.5, 2.8, IF((E18*0.6+F18*0.4)>5.5, 5.2, (E18*0.6+F18*0.4))) | H18: ASTROS | I18: =VLOOKUP(H18, 'MLB Data'!$B$5:$D$34, 3, FALSE) | J18: BURROWS | K18: 3.86 | L18: =VLOOKUP(H18, 'MLB Data'!$F$2:$H$34, 3, FALSE) | M18: =IF((K18*0.6+L18*0.4)<2.5, 2.8, IF((K18*0.6+L18*0.4)>5.5, 5.2, (K18*0.6+L18*0.4))) | O18: =(C18/100) * 4.45 * (M18 / 4.2) * T18 | P18: =(I18/100) * 4.45 * (G18 / 4.2) * T18 | Q18: =(O18+P18) | S18: =H18 | T18: =IF(S18="ROCKIES",1.13,IF(S18="ATHLETICS",1.03,IF(S18="ROYALS",1.03,IF(S18="TWINS",1,IF(S18="TIGERS",1,IF(S18="MARLINS",1.01,IF(S18="REDS",1.05,IF(S18="RED SOX",1.04,IF(S18="YANKEES",1.02,IF(S18="DODGERS",0.99,IF(S18="PADRES",0.96,IF(S18="CUBS",0.98,IF(S18="GIANTS",0.97,IF(S18="MARINERS",0.94,IF(S18="RANGERS",1,IF(S18="ASTROS",0.99,IF(S18="BRAVES",1,IF(S18="METS",0.96,IF(S18="PHILLIES",1.02,IF(S18="BLUE JAYS",1.01,IF(S18="ORIOLES",0.99,IF(S18="RAYS",1.01,IF(S18="GUARDIANS",0.99,IF(S18="WHITE SOX",0.98,IF(S18="ANGELS",1.01,IF(S18="D-BACKS",1.01,IF(S18="BREWERS",0.99,IF(S18="CARDINALS",0.96,IF(S18="PIRATES",1.02,IF(S18="NATIONALS",1,1))))))))))))))))))))))))))))))*IF(W18="",1,(1+((W18-70)/10*0.035)))*IF(U18="DOME",1,IF(U18="IN",1-(V18*0.01),IF(U18="OUT",1+(V18*0.01),IF(OR(U18="L-R",U18="R-L"),1+(V18*0.005),1)))) | U18: DOME | W18: 81 | Y18: =B18 & " vs. " & H18 | Z18: =TRIM(LEFT(Y18, FIND("vs.", Y18)-1)) | AA18: =TRIM(MID(Y18, FIND(" vs. ", Y18)+4, 100)) | AB18: =IF(Q18 > VALUE(AC18), "O " & AC18, IF(Q18 < VALUE(AC18), "U " & AC18, AC18)) | AC18: =IF(OR(O18="-", P18="-"), "-", MROUND(O18 + P18, 0.5)) | AD18: =VALUE(TRIM(RIGHT(AF18, LEN(AF18) - FIND(" ", AF18)))) | AE18: =LEFT(AF18,FIND(" ",AF18)-1) | AF18: =IF(OR(O18="-", P18="-"), "-", IF(MROUND(ABS(O18-P18),0.5)<=0.5, IF(O18>P18, B18 & " ML", H18 & " ML"), IF(MROUND(ABS(O18-P18),0.5)=1, IF(O18>P18, H18 & " +1.5", B18 & " +1.5"), IF(O18>P18, B18 & " -1.5", H18 & " -1.5") ) ) ) | AG18: =_xlfn.LET( _xlpm.winA, O18^1.83 / (O18^1.83 + P18^1.83), _xlpm.winB, 1 - _xlpm.winA, _xlpm.oddsA, IF(_xlpm.winA >= 0.5, "-" & ROUND(_xlpm.winA / (1 - _xlpm.winA) * 100, 0), "+" & ROUND((1 - _xlpm.winA) / _xlpm.winA * 100, 0)), _xlpm.oddsB, IF(_xlpm.winB >= 0.5, "-" & ROUND(_xlpm.winB / (1 - _xlpm.winB) * 100, 0), "+" & ROUND((1 - _xlpm.winB) / _xlpm.winB * 100, 0)), _xlpm.oddsA & " / " & _xlpm.oddsB)
A19: 46108 | B19: TIGERS | C19: =VLOOKUP(B19, 'MLB Data'!$B$5:$D$34, 3, FALSE) | D19: VALDEZ | E19: 3.34 | F19: =VLOOKUP(B19, 'MLB Data'!$F$2:$H$34, 3, FALSE) | G19: =IF((E19*0.6+F19*0.4)<2.5, 2.8, IF((E19*0.6+F19*0.4)>5.5, 5.2, (E19*0.6+F19*0.4))) | H19: PADRES | I19: =VLOOKUP(H19, 'MLB Data'!$B$5:$D$34, 3, FALSE) | J19: KING | K19: 4.2 | L19: =VLOOKUP(H19, 'MLB Data'!$F$2:$H$34, 3, FALSE) | M19: =IF((K19*0.6+L19*0.4)<2.5, 2.8, IF((K19*0.6+L19*0.4)>5.5, 5.2, (K19*0.6+L19*0.4))) | O19: =(C19/100) * 4.45 * (M19 / 4.2) * T19 | P19: =(I19/100) * 4.45 * (G19 / 4.2) * T19 | Q19: =(O19+P19) | S19: =H19 | T19: =IF(S19="ROCKIES",1.13,IF(S19="ATHLETICS",1.03,IF(S19="ROYALS",1.03,IF(S19="TWINS",1,IF(S19="TIGERS",1,IF(S19="MARLINS",1.01,IF(S19="REDS",1.05,IF(S19="RED SOX",1.04,IF(S19="YANKEES",1.02,IF(S19="DODGERS",0.99,IF(S19="PADRES",0.96,IF(S19="CUBS",0.98,IF(S19="GIANTS",0.97,IF(S19="MARINERS",0.94,IF(S19="RANGERS",1,IF(S19="ASTROS",0.99,IF(S19="BRAVES",1,IF(S19="METS",0.96,IF(S19="PHILLIES",1.02,IF(S19="BLUE JAYS",1.01,IF(S19="ORIOLES",0.99,IF(S19="RAYS",1.01,IF(S19="GUARDIANS",0.99,IF(S19="WHITE SOX",0.98,IF(S19="ANGELS",1.01,IF(S19="D-BACKS",1.01,IF(S19="BREWERS",0.99,IF(S19="CARDINALS",0.96,IF(S19="PIRATES",1.02,IF(S19="NATIONALS",1,1))))))))))))))))))))))))))))))*IF(W19="",1,(1+((W19-70)/10*0.035)))*IF(U19="DOME",1,IF(U19="IN",1-(V19*0.01),IF(U19="OUT",1+(V19*0.01),IF(OR(U19="L-R",U19="R-L"),1+(V19*0.005),1)))) | U19: OUT | W19: 71 | Y19: =B19 & " vs. " & H19 | Z19: =TRIM(LEFT(Y19, FIND("vs.", Y19)-1)) | AA19: =TRIM(MID(Y19, FIND(" vs. ", Y19)+4, 100)) | AB19: =IF(Q19 > VALUE(AC19), "O " & AC19, IF(Q19 < VALUE(AC19), "U " & AC19, AC19)) | AC19: =IF(OR(O19="-", P19="-"), "-", MROUND(O19 + P19, 0.5)) | AD19: =VALUE(TRIM(RIGHT(AF19, LEN(AF19) - FIND(" ", AF19)))) | AE19: =LEFT(AF19,FIND(" ",AF19)-1) | AF19: =IF(OR(O19="-", P19="-"), "-", IF(MROUND(ABS(O19-P19),0.5)<=0.5, IF(O19>P19, B19 & " ML", H19 & " ML"), IF(MROUND(ABS(O19-P19),0.5)=1, IF(O19>P19, H19 & " +1.5", B19 & " +1.5"), IF(O19>P19, B19 & " -1.5", H19 & " -1.5") ) ) ) | AG19: =_xlfn.LET( _xlpm.winA, O19^1.83 / (O19^1.83 + P19^1.83), _xlpm.winB, 1 - _xlpm.winA, _xlpm.oddsA, IF(_xlpm.winA >= 0.5, "-" & ROUND(_xlpm.winA / (1 - _xlpm.winA) * 100, 0), "+" & ROUND((1 - _xlpm.winA) / _xlpm.winA * 100, 0)), _xlpm.oddsB, IF(_xlpm.winB >= 0.5, "-" & ROUND(_xlpm.winB / (1 - _xlpm.winB) * 100, 0), "+" & ROUND((1 - _xlpm.winB) / _xlpm.winB * 100, 0)), _xlpm.oddsA & " / " & _xlpm.oddsB)
A20: 46108 | B20: GUARDIANS | C20: =VLOOKUP(B20, 'MLB Data'!$B$5:$D$34, 3, FALSE) | D20: WILLIAMS | E20: 4.08 | F20: =VLOOKUP(B20, 'MLB Data'!$F$2:$H$34, 3, FALSE) | G20: =IF((E20*0.6+F20*0.4)<2.5, 2.8, IF((E20*0.6+F20*0.4)>5.5, 5.2, (E20*0.6+F20*0.4))) | H20: MARINERS | I20: =VLOOKUP(H20, 'MLB Data'!$B$5:$D$34, 3, FALSE) | J20: KIRBY | K20: 3.25 | L20: =VLOOKUP(H20, 'MLB Data'!$F$2:$H$34, 3, FALSE) | M20: =IF((K20*0.6+L20*0.4)<2.5, 2.8, IF((K20*0.6+L20*0.4)>5.5, 5.2, (K20*0.6+L20*0.4))) | O20: =(C20/100) * 4.45 * (M20 / 4.2) * T20 | P20: =(I20/100) * 4.45 * (G20 / 4.2) * T20 | Q20: =(O20+P20) | S20: =H20 | T20: =IF(S20="ROCKIES",1.13,IF(S20="ATHLETICS",1.03,IF(S20="ROYALS",1.03,IF(S20="TWINS",1,IF(S20="TIGERS",1,IF(S20="MARLINS",1.01,IF(S20="REDS",1.05,IF(S20="RED SOX",1.04,IF(S20="YANKEES",1.02,IF(S20="DODGERS",0.99,IF(S20="PADRES",0.96,IF(S20="CUBS",0.98,IF(S20="GIANTS",0.97,IF(S20="MARINERS",0.94,IF(S20="RANGERS",1,IF(S20="ASTROS",0.99,IF(S20="BRAVES",1,IF(S20="METS",0.96,IF(S20="PHILLIES",1.02,IF(S20="BLUE JAYS",1.01,IF(S20="ORIOLES",0.99,IF(S20="RAYS",1.01,IF(S20="GUARDIANS",0.99,IF(S20="WHITE SOX",0.98,IF(S20="ANGELS",1.01,IF(S20="D-BACKS",1.01,IF(S20="BREWERS",0.99,IF(S20="CARDINALS",0.96,IF(S20="PIRATES",1.02,IF(S20="NATIONALS",1,1))))))))))))))))))))))))))))))*IF(W20="",1,(1+((W20-70)/10*0.035)))*IF(U20="DOME",1,IF(U20="IN",1-(V20*0.01),IF(U20="OUT",1+(V20*0.01),IF(OR(U20="L-R",U20="R-L"),1+(V20*0.005),1)))) | U20: IN | W20: 50 | Y20: =B20 & " vs. " & H20 | Z20: =TRIM(LEFT(Y20, FIND("vs.", Y20)-1)) | AA20: =TRIM(MID(Y20, FIND(" vs. ", Y20)+4, 100)) | AB20: =IF(Q20 > VALUE(AC20), "O " & AC20, IF(Q20 < VALUE(AC20), "U " & AC20, AC20)) | AC20: =IF(OR(O20="-", P20="-"), "-", MROUND(O20 + P20, 0.5)) | AD20: =VALUE(TRIM(RIGHT(AF20, LEN(AF20) - FIND(" ", AF20)))) | AE20: =LEFT(AF20,FIND(" ",AF20)-1) | AF20: =IF(OR(O20="-", P20="-"), "-", IF(MROUND(ABS(O20-P20),0.5)<=0.5, IF(O20>P20, B20 & " ML", H20 & " ML"), IF(MROUND(ABS(O20-P20),0.5)=1, IF(O20>P20, H20 & " +1.5", B20 & " +1.5"), IF(O20>P20, B20 & " -1.5", H20 & " -1.5") ) ) ) | AG20: =_xlfn.LET( _xlpm.winA, O20^1.83 / (O20^1.83 + P20^1.83), _xlpm.winB, 1 - _xlpm.winA, _xlpm.oddsA, IF(_xlpm.winA >= 0.5, "-" & ROUND(_xlpm.winA / (1 - _xlpm.winA) * 100, 0), "+" & ROUND((1 - _xlpm.winA) / _xlpm.winA * 100, 0)), _xlpm.oddsB, IF(_xlpm.winB >= 0.5, "-" & ROUND(_xlpm.winB / (1 - _xlpm.winB) * 100, 0), "+" & ROUND((1 - _xlpm.winB) / _xlpm.winB * 100, 0)), _xlpm.oddsA & " / " & _xlpm.oddsB)
A21: 46108 | B21: D-BACKS | C21: =VLOOKUP(B21, 'MLB Data'!$B$5:$D$34, 3, FALSE) | D21: NELSON | E21: 4.22 | F21: =VLOOKUP(B21, 'MLB Data'!$F$2:$H$34, 3, FALSE) | G21: =IF((E21*0.6+F21*0.4)<2.5, 2.8, IF((E21*0.6+F21*0.4)>5.5, 5.2, (E21*0.6+F21*0.4))) | H21: DODGERS | I21: =VLOOKUP(H21, 'MLB Data'!$B$5:$D$34, 3, FALSE) | J21: SHEEHAN | K21: 3.01 | L21: =VLOOKUP(H21, 'MLB Data'!$F$2:$H$34, 3, FALSE) | M21: =IF((K21*0.6+L21*0.4)<2.5, 2.8, IF((K21*0.6+L21*0.4)>5.5, 5.2, (K21*0.6+L21*0.4))) | O21: =(C21/100) * 4.45 * (M21 / 4.2) * T21 | P21: =(I21/100) * 4.45 * (G21 / 4.2) * T21 | Q21: =(O21+P21) | S21: =H21 | T21: =IF(S21="ROCKIES",1.13,IF(S21="ATHLETICS",1.03,IF(S21="ROYALS",1.03,IF(S21="TWINS",1,IF(S21="TIGERS",1,IF(S21="MARLINS",1.01,IF(S21="REDS",1.05,IF(S21="RED SOX",1.04,IF(S21="YANKEES",1.02,IF(S21="DODGERS",0.99,IF(S21="PADRES",0.96,IF(S21="CUBS",0.98,IF(S21="GIANTS",0.97,IF(S21="MARINERS",0.94,IF(S21="RANGERS",1,IF(S21="ASTROS",0.99,IF(S21="BRAVES",1,IF(S21="METS",0.96,IF(S21="PHILLIES",1.02,IF(S21="BLUE JAYS",1.01,IF(S21="ORIOLES",0.99,IF(S21="RAYS",1.01,IF(S21="GUARDIANS",0.99,IF(S21="WHITE SOX",0.98,IF(S21="ANGELS",1.01,IF(S21="D-BACKS",1.01,IF(S21="BREWERS",0.99,IF(S21="CARDINALS",0.96,IF(S21="PIRATES",1.02,IF(S21="NATIONALS",1,1))))))))))))))))))))))))))))))*IF(W21="",1,(1+((W21-70)/10*0.035)))*IF(U21="DOME",1,IF(U21="IN",1-(V21*0.01),IF(U21="OUT",1+(V21*0.01),IF(OR(U21="L-R",U21="R-L"),1+(V21*0.005),1)))) | U21: IN | W21: 50 | Y21: =B21 & " vs. " & H21 | Z21: =TRIM(LEFT(Y21, FIND("vs.", Y21)-1)) | AA21: =TRIM(MID(Y21, FIND(" vs. ", Y21)+4, 100)) | AB21: =IF(Q21 > VALUE(AC21), "O " & AC21, IF(Q21 < VALUE(AC21), "U " & AC21, AC21)) | AC21: =IF(OR(O21="-", P21="-"), "-", MROUND(O21 + P21, 0.5)) | AD21: =VALUE(TRIM(RIGHT(AF21, LEN(AF21) - FIND(" ", AF21)))) | AE21: =LEFT(AF21,FIND(" ",AF21)-1) | AF21: =IF(OR(O21="-", P21="-"), "-", IF(MROUND(ABS(O21-P21),0.5)<=0.5, IF(O21>P21, B21 & " ML", H21 & " ML"), IF(MROUND(ABS(O21-P21),0.5)=1, IF(O21>P21, H21 & " +1.5", B21 & " +1.5"), IF(O21>P21, B21 & " -1.5", H21 & " -1.5") ) ) ) | AG21: =_xlfn.LET( _xlpm.winA, O21^1.83 / (O21^1.83 + P21^1.83), _xlpm.winB, 1 - _xlpm.winA, _xlpm.oddsA, IF(_xlpm.winA >= 0.5, "-" & ROUND(_xlpm.winA / (1 - _xlpm.winA) * 100, 0), "+" & ROUND((1 - _xlpm.winA) / _xlpm.winA * 100, 0)), _xlpm.oddsB, IF(_xlpm.winB >= 0.5, "-" & ROUND(_xlpm.winB / (1 - _xlpm.winB) * 100, 0), "+" & ROUND((1 - _xlpm.winB) / _xlpm.winB * 100, 0)), _xlpm.oddsA & " / " & _xlpm.oddsB)
A22: 46109 | B22: RAYS | C22: =VLOOKUP(B22, 'MLB Data'!$B$5:$D$34, 3, FALSE) | D22: BOYLE | E22: 4.38 | F22: =VLOOKUP(B22, 'MLB Data'!$F$2:$H$34, 3, FALSE) | G22: =IF((E22*0.6+F22*0.4)<2.5, 2.8, IF((E22*0.6+F22*0.4)>5.5, 5.2, (E22*0.6+F22*0.4))) | H22: CARDINALS | I22: =VLOOKUP(H22, 'MLB Data'!$B$5:$D$34, 3, FALSE) | J22: MCGREEVY | K22: 4.35 | L22: =VLOOKUP(H22, 'MLB Data'!$F$2:$H$34, 3, FALSE) | M22: =IF((K22*0.6+L22*0.4)<2.5, 2.8, IF((K22*0.6+L22*0.4)>5.5, 5.2, (K22*0.6+L22*0.4))) | O22: =(C22/100) * 4.45 * (M22 / 4.2) * T22 | P22: =(I22/100) * 4.45 * (G22 / 4.2) * T22 | Q22: =(O22+P22) | S22: =H22 | T22: =IF(S22="ROCKIES",1.13,IF(S22="ATHLETICS",1.03,IF(S22="ROYALS",1.03,IF(S22="TWINS",1,IF(S22="TIGERS",1,IF(S22="MARLINS",1.01,IF(S22="REDS",1.05,IF(S22="RED SOX",1.04,IF(S22="YANKEES",1.02,IF(S22="DODGERS",0.99,IF(S22="PADRES",0.96,IF(S22="CUBS",0.98,IF(S22="GIANTS",0.97,IF(S22="MARINERS",0.94,IF(S22="RANGERS",1,IF(S22="ASTROS",0.99,IF(S22="BRAVES",1,IF(S22="METS",0.96,IF(S22="PHILLIES",1.02,IF(S22="BLUE JAYS",1.01,IF(S22="ORIOLES",0.99,IF(S22="RAYS",1.01,IF(S22="GUARDIANS",0.99,IF(S22="WHITE SOX",0.98,IF(S22="ANGELS",1.01,IF(S22="D-BACKS",1.01,IF(S22="BREWERS",0.99,IF(S22="CARDINALS",0.96,IF(S22="PIRATES",1.02,IF(S22="NATIONALS",1,1))))))))))))))))))))))))))))))*IF(W22="",1,(1+((W22-70)/10*0.035)))*IF(U22="DOME",1,IF(U22="IN",1-(V22*0.01),IF(U22="OUT",1+(V22*0.01),IF(OR(U22="L-R",U22="R-L"),1+(V22*0.005),1)))) | U22: R-L | W22: 51 | Y22: =B22 & " vs. " & H22 | Z22: =TRIM(LEFT(Y22, FIND("vs.", Y22)-1)) | AA22: =TRIM(MID(Y22, FIND(" vs. ", Y22)+4, 100)) | AB22: =IF(Q22 > VALUE(AC22), "O " & AC22, IF(Q22 < VALUE(AC22), "U " & AC22, AC22)) | AC22: =IF(OR(O22="-", P22="-"), "-", MROUND(O22 + P22, 0.5)) | AD22: =VALUE(TRIM(RIGHT(AF22, LEN(AF22) - FIND(" ", AF22)))) | AE22: =LEFT(AF22,FIND(" ",AF22)-1) | AF22: =IF(OR(O22="-", P22="-"), "-", IF(MROUND(ABS(O22-P22),0.5)<=0.5, IF(O22>P22, B22 & " ML", H22 & " ML"), IF(MROUND(ABS(O22-P22),0.5)=1, IF(O22>P22, H22 & " +1.5", B22 & " +1.5"), IF(O22>P22, B22 & " -1.5", H22 & " -1.5") ) ) ) | AG22: =_xlfn.LET( _xlpm.winA, O22^1.83 / (O22^1.83 + P22^1.83), _xlpm.winB, 1 - _xlpm.winA, _xlpm.oddsA, IF(_xlpm.winA >= 0.5, "-" & ROUND(_xlpm.winA / (1 - _xlpm.winA) * 100, 0), "+" & ROUND((1 - _xlpm.winA) / _xlpm.winA * 100, 0)), _xlpm.oddsB, IF(_xlpm.winB >= 0.5, "-" & ROUND(_xlpm.winB / (1 - _xlpm.winB) * 100, 0), "+" & ROUND((1 - _xlpm.winB) / _xlpm.winB * 100, 0)), _xlpm.oddsA & " / " & _xlpm.oddsB)
A23: 46109 | B23: NATIONALS | C23: =VLOOKUP(B23, 'MLB Data'!$B$5:$D$34, 3, FALSE) | D23: MIKOLAS | E23: 4.83 | F23: =VLOOKUP(B23, 'MLB Data'!$F$2:$H$34, 3, FALSE) | G23: =IF((E23*0.6+F23*0.4)<2.5, 2.8, IF((E23*0.6+F23*0.4)>5.5, 5.2, (E23*0.6+F23*0.4))) | H23: CUBS | I23: =VLOOKUP(H23, 'MLB Data'!$B$5:$D$34, 3, FALSE) | J23: HORTON | K23: 4.31 | L23: =VLOOKUP(H23, 'MLB Data'!$F$2:$H$34, 3, FALSE) | M23: =IF((K23*0.6+L23*0.4)<2.5, 2.8, IF((K23*0.6+L23*0.4)>5.5, 5.2, (K23*0.6+L23*0.4))) | O23: =(C23/100) * 4.45 * (M23 / 4.2) * T23 | P23: =(I23/100) * 4.45 * (G23 / 4.2) * T23 | Q23: =(O23+P23) | S23: =H23 | T23: =IF(S23="ROCKIES",1.13,IF(S23="ATHLETICS",1.03,IF(S23="ROYALS",1.03,IF(S23="TWINS",1,IF(S23="TIGERS",1,IF(S23="MARLINS",1.01,IF(S23="REDS",1.05,IF(S23="RED SOX",1.04,IF(S23="YANKEES",1.02,IF(S23="DODGERS",0.99,IF(S23="PADRES",0.96,IF(S23="CUBS",0.98,IF(S23="GIANTS",0.97,IF(S23="MARINERS",0.94,IF(S23="RANGERS",1,IF(S23="ASTROS",0.99,IF(S23="BRAVES",1,IF(S23="METS",0.96,IF(S23="PHILLIES",1.02,IF(S23="BLUE JAYS",1.01,IF(S23="ORIOLES",0.99,IF(S23="RAYS",1.01,IF(S23="GUARDIANS",0.99,IF(S23="WHITE SOX",0.98,IF(S23="ANGELS",1.01,IF(S23="D-BACKS",1.01,IF(S23="BREWERS",0.99,IF(S23="CARDINALS",0.96,IF(S23="PIRATES",1.02,IF(S23="NATIONALS",1,1))))))))))))))))))))))))))))))*IF(W23="",1,(1+((W23-70)/10*0.035)))*IF(U23="DOME",1,IF(U23="IN",1-(V23*0.01),IF(U23="OUT",1+(V23*0.01),IF(OR(U23="L-R",U23="R-L"),1+(V23*0.005),1)))) | U23: OUT | W23: 38 | Y23: =B23 & " vs. " & H23 | Z23: =TRIM(LEFT(Y23, FIND("vs.", Y23)-1)) | AA23: =TRIM(MID(Y23, FIND(" vs. ", Y23)+4, 100)) | AB23: =IF(Q23 > VALUE(AC23), "O " & AC23, IF(Q23 < VALUE(AC23), "U " & AC23, AC23)) | AC23: =IF(OR(O23="-", P23="-"), "-", MROUND(O23 + P23, 0.5)) | AD23: =VALUE(TRIM(RIGHT(AF23, LEN(AF23) - FIND(" ", AF23)))) | AE23: =LEFT(AF23,FIND(" ",AF23)-1) | AF23: =IF(OR(O23="-", P23="-"), "-", IF(MROUND(ABS(O23-P23),0.5)<=0.5, IF(O23>P23, B23 & " ML", H23 & " ML"), IF(MROUND(ABS(O23-P23),0.5)=1, IF(O23>P23, H23 & " +1.5", B23 & " +1.5"), IF(O23>P23, B23 & " -1.5", H23 & " -1.5") ) ) ) | AG23: =_xlfn.LET( _xlpm.winA, O23^1.83 / (O23^1.83 + P23^1.83), _xlpm.winB, 1 - _xlpm.winA, _xlpm.oddsA, IF(_xlpm.winA >= 0.5, "-" & ROUND(_xlpm.winA / (1 - _xlpm.winA) * 100, 0), "+" & ROUND((1 - _xlpm.winA) / _xlpm.winA * 100, 0)), _xlpm.oddsB, IF(_xlpm.winB >= 0.5, "-" & ROUND(_xlpm.winB / (1 - _xlpm.winB) * 100, 0), "+" & ROUND((1 - _xlpm.winB) / _xlpm.winB * 100, 0)), _xlpm.oddsA & " / " & _xlpm.oddsB)
A24: 46109 | B24: ATHLETICS | C24: =VLOOKUP(B24, 'MLB Data'!$B$5:$D$34, 3, FALSE) | D24: SPRINGS | E24: 4.78 | F24: =VLOOKUP(B24, 'MLB Data'!$F$2:$H$34, 3, FALSE) | G24: =IF((E24*0.6+F24*0.4)<2.5, 2.8, IF((E24*0.6+F24*0.4)>5.5, 5.2, (E24*0.6+F24*0.4))) | H24: BLUE JAYS | I24: =VLOOKUP(H24, 'MLB Data'!$B$5:$D$34, 3, FALSE) | J24: CEASE | K24: 3.56 | L24: =VLOOKUP(H24, 'MLB Data'!$F$2:$H$34, 3, FALSE) | M24: =IF((K24*0.6+L24*0.4)<2.5, 2.8, IF((K24*0.6+L24*0.4)>5.5, 5.2, (K24*0.6+L24*0.4))) | O24: =(C24/100) * 4.45 * (M24 / 4.2) * T24 | P24: =(I24/100) * 4.45 * (G24 / 4.2) * T24 | Q24: =(O24+P24) | S24: =H24 | T24: =IF(S24="ROCKIES",1.13,IF(S24="ATHLETICS",1.03,IF(S24="ROYALS",1.03,IF(S24="TWINS",1,IF(S24="TIGERS",1,IF(S24="MARLINS",1.01,IF(S24="REDS",1.05,IF(S24="RED SOX",1.04,IF(S24="YANKEES",1.02,IF(S24="DODGERS",0.99,IF(S24="PADRES",0.96,IF(S24="CUBS",0.98,IF(S24="GIANTS",0.97,IF(S24="MARINERS",0.94,IF(S24="RANGERS",1,IF(S24="ASTROS",0.99,IF(S24="BRAVES",1,IF(S24="METS",0.96,IF(S24="PHILLIES",1.02,IF(S24="BLUE JAYS",1.01,IF(S24="ORIOLES",0.99,IF(S24="RAYS",1.01,IF(S24="GUARDIANS",0.99,IF(S24="WHITE SOX",0.98,IF(S24="ANGELS",1.01,IF(S24="D-BACKS",1.01,IF(S24="BREWERS",0.99,IF(S24="CARDINALS",0.96,IF(S24="PIRATES",1.02,IF(S24="NATIONALS",1,1))))))))))))))))))))))))))))))*IF(W24="",1,(1+((W24-70)/10*0.035)))*IF(U24="DOME",1,IF(U24="IN",1-(V24*0.01),IF(U24="OUT",1+(V24*0.01),IF(OR(U24="L-R",U24="R-L"),1+(V24*0.005),1)))) | U24: DOME | Y24: =B24 & " vs. " & H24 | Z24: =TRIM(LEFT(Y24, FIND("vs.", Y24)-1)) | AA24: =TRIM(MID(Y24, FIND(" vs. ", Y24)+4, 100)) | AB24: =IF(Q24 > VALUE(AC24), "O " & AC24, IF(Q24 < VALUE(AC24), "U " & AC24, AC24)) | AC24: =IF(OR(O24="-", P24="-"), "-", MROUND(O24 + P24, 0.5)) | AD24: =VALUE(TRIM(RIGHT(AF24, LEN(AF24) - FIND(" ", AF24)))) | AE24: =LEFT(AF24,FIND(" ",AF24)-1) | AF24: =IF(OR(O24="-", P24="-"), "-", IF(MROUND(ABS(O24-P24),0.5)<=0.5, IF(O24>P24, B24 & " ML", H24 & " ML"), IF(MROUND(ABS(O24-P24),0.5)=1, IF(O24>P24, H24 & " +1.5", B24 & " +1.5"), IF(O24>P24, B24 & " -1.5", H24 & " -1.5") ) ) ) | AG24: =_xlfn.LET( _xlpm.winA, O24^1.83 / (O24^1.83 + P24^1.83), _xlpm.winB, 1 - _xlpm.winA, _xlpm.oddsA, IF(_xlpm.winA >= 0.5, "-" & ROUND(_xlpm.winA / (1 - _xlpm.winA) * 100, 0), "+" & ROUND((1 - _xlpm.winA) / _xlpm.winA * 100, 0)), _xlpm.oddsB, IF(_xlpm.winB >= 0.5, "-" & ROUND(_xlpm.winB / (1 - _xlpm.winB) * 100, 0), "+" & ROUND((1 - _xlpm.winB) / _xlpm.winB * 100, 0)), _xlpm.oddsA & " / " & _xlpm.oddsB)
A25: 46109 | B25: TWINS | C25: =VLOOKUP(B25, 'MLB Data'!$B$5:$D$34, 3, FALSE) | D25: BRADLEY | E25: 4.37 | F25: =VLOOKUP(B25, 'MLB Data'!$F$2:$H$34, 3, FALSE) | G25: =IF((E25*0.6+F25*0.4)<2.5, 2.8, IF((E25*0.6+F25*0.4)>5.5, 5.2, (E25*0.6+F25*0.4))) | H25: ORIOLES | I25: =VLOOKUP(H25, 'MLB Data'!$B$5:$D$34, 3, FALSE) | J25: BRADISH | K25: 2.67 | L25: =VLOOKUP(H25, 'MLB Data'!$F$2:$H$34, 3, FALSE) | M25: =IF((K25*0.6+L25*0.4)<2.5, 2.8, IF((K25*0.6+L25*0.4)>5.5, 5.2, (K25*0.6+L25*0.4))) | O25: =(C25/100) * 4.45 * (M25 / 4.2) * T25 | P25: =(I25/100) * 4.45 * (G25 / 4.2) * T25 | Q25: =(O25+P25) | S25: =H25 | T25: =IF(S25="ROCKIES",1.13,IF(S25="ATHLETICS",1.03,IF(S25="ROYALS",1.03,IF(S25="TWINS",1,IF(S25="TIGERS",1,IF(S25="MARLINS",1.01,IF(S25="REDS",1.05,IF(S25="RED SOX",1.04,IF(S25="YANKEES",1.02,IF(S25="DODGERS",0.99,IF(S25="PADRES",0.96,IF(S25="CUBS",0.98,IF(S25="GIANTS",0.97,IF(S25="MARINERS",0.94,IF(S25="RANGERS",1,IF(S25="ASTROS",0.99,IF(S25="BRAVES",1,IF(S25="METS",0.96,IF(S25="PHILLIES",1.02,IF(S25="BLUE JAYS",1.01,IF(S25="ORIOLES",0.99,IF(S25="RAYS",1.01,IF(S25="GUARDIANS",0.99,IF(S25="WHITE SOX",0.98,IF(S25="ANGELS",1.01,IF(S25="D-BACKS",1.01,IF(S25="BREWERS",0.99,IF(S25="CARDINALS",0.96,IF(S25="PIRATES",1.02,IF(S25="NATIONALS",1,1))))))))))))))))))))))))))))))*IF(W25="",1,(1+((W25-70)/10*0.035)))*IF(U25="DOME",1,IF(U25="IN",1-(V25*0.01),IF(U25="OUT",1+(V25*0.01),IF(OR(U25="L-R",U25="R-L"),1+(V25*0.005),1)))) | U25: L-R | W25: 48 | Y25: =B25 & " vs. " & H25 | Z25: =TRIM(LEFT(Y25, FIND("vs.", Y25)-1)) | AA25: =TRIM(MID(Y25, FIND(" vs. ", Y25)+4, 100)) | AB25: =IF(Q25 > VALUE(AC25), "O " & AC25, IF(Q25 < VALUE(AC25), "U " & AC25, AC25)) | AC25: =IF(OR(O25="-", P25="-"), "-", MROUND(O25 + P25, 0.5)) | AD25: =VALUE(TRIM(RIGHT(AF25, LEN(AF25) - FIND(" ", AF25)))) | AE25: =LEFT(AF25,FIND(" ",AF25)-1) | AF25: =IF(OR(O25="-", P25="-"), "-", IF(MROUND(ABS(O25-P25),0.5)<=0.5, IF(O25>P25, B25 & " ML", H25 & " ML"), IF(MROUND(ABS(O25-P25),0.5)=1, IF(O25>P25, H25 & " +1.5", B25 & " +1.5"), IF(O25>P25, B25 & " -1.5", H25 & " -1.5") ) ) ) | AG25: =_xlfn.LET( _xlpm.winA, O25^1.83 / (O25^1.83 + P25^1.83), _xlpm.winB, 1 - _xlpm.winA, _xlpm.oddsA, IF(_xlpm.winA >= 0.5, "-" & ROUND(_xlpm.winA / (1 - _xlpm.winA) * 100, 0), "+" & ROUND((1 - _xlpm.winA) / _xlpm.winA * 100, 0)), _xlpm.oddsB, IF(_xlpm.winB >= 0.5, "-" & ROUND(_xlpm.winB / (1 - _xlpm.winB) * 100, 0), "+" & ROUND((1 - _xlpm.winB) / _xlpm.winB * 100, 0)), _xlpm.oddsA & " / " & _xlpm.oddsB)
